Workbook

Sheet Допущения
A1: Допущения: ECCO Kids — медиаплан Яндекс Директ
A2: Бюджет канала фиксирую 1 000 000 ₽/мес без НДС — это расход для ДРР. НДС 22% в KPI не мешаю. AOV 4 250 ₽ — допущение с витрины kids/boys, не 1С. Цель одна: «Покупка на сайте». Жёлтые ячейки — входы модели.
A4: Блок | B4: Параметр | C4: Значение | D4: Ед. | E4: Источник / логика | F4: Как используется
A5: Исходные данные ТЗ | B5: Бренд / посадка | C5: ECCO, kids, boys, посадочная kids/boys/ | D5: текст | E5: ТЗ экзамена (часть 3) | F5: Фильтр семантики и объявлений
A6: Исходные данные ТЗ | B6: Канал | C6: Только Яндекс Директ | D6: текст | E6: ТЗ: другие каналы запрещены | F6: Все строки медиаплана
A7: Исходные данные ТЗ | B7: Месячный бюджет без НДС | C7: 1000000 | D7: ₽ | E7: ТЗ: 1 млн ₽/мес без НДС | F7: База бюджета инструментов
A8: Исходные данные ТЗ | B8: Ставка НДС | C8: 0.22 | D8: % | E8: ТЗ: НДС 22% | F8: Справка; KPI считаем без НДС
A9: Исходные данные ТЗ | B9: Горизонт, месяцев | C9: 12 | D9: мес | E9: ТЗ: 12 месяцев | F9: Число столбцов сводки
A10: Исходные данные ТЗ | B10: Целевое действие | C10: Покупка на сайте (Метрика) | D10: текст | E10: ТЗ: цель «Покупка на сайте» | F10: CR и покупки
A11: Исходные данные ТЗ | B11: KPI эффективности | C11: ДРР = расход без НДС / выручка | D11: текст | E11: ТЗ: формула ДРР | F11: Листы сводок
A12: Исходные данные ТЗ | B12: Коридор ДРР (ориентир) | C12: 15–25% | D12: текст | E12: ТЗ: коридор эффективности | F12: Проверка сводки за год
A13: С сайта / витрины | B13: Средний чек (AOV) | C13: 4250 | D13: ₽ | E13: Витрина ecco-shoes.kz kids: 5 SKU 24 900–54 900 ₸ ≈ 4 150–9 150 ₽, медиана ближе к низу; округлили | F13: Выручка = покупки × AOV
A14: С сайта / витрины | B14: Ценовой якорь витрины | C14: 24900–54900 ₸ | D14: текст | E14: Карточки kids/boys на сайте (просмотр 2026-04) | F14: Обоснование AOV
A15: С сайта / витрины | B15: Курс ориентир | C15: 1 ₸ ≈ 0,167 ₽ | D15: текст | E15: Округление для перевода витрины в рубли | F15: Только пояснение AOV
A16: Наше усмотрение | B16: Старт горизонта | C16: 46266 | D16: дата | E16: Приняли сентябрь — школьный сезон kids, полный год до авг 2027 | F16: Подписи месяцев
A17: Наше усмотрение | B17: Число кампаний ЕПК | C17: 6 | D17: шт | E17: ТЗ: 4–7 инструментов; взяли 6 ЕПК (3 поиск + 3 сети) | F17: Лист «Инструменты»
A18: Наше усмотрение | B18: Тип кампании | C18: ЕПК | D18: текст | E18: В Директе 2026 тип кампании = ЕПК; товарное/графика — тип объявления | F18: Колонка «Тип кампании»
A19: Наше усмотрение | B19: Сезонность бюджета | C19: Равномерно 1/12 | D19: текст | E19: ТЗ не задаёт сезонность; бюджет не плаваем по месяцам | F19: Медиаплан на год
A20: Наше усмотрение | B20: Модель воронки | C20: Показы → клики → покупки → выручка | D20: текст | E20: Без промежуточной заявки: цель ТЗ — покупка | F20: Формулы кликов/покупок
A21: Наше усмотрение | B21: Округление денег | C21: До целых ₽ | D21: текст | E21: ROUND в формулах бюджета/выручки | F21: Все денежные KPI
A22: Наше усмотрение | B22: Места показа в одной ЕПК | C22: Не смешиваем Поиск и РСЯ | D22: текст | E22: Head of PPC: грязный CR и нечитаемый аукцион | F22: 6 отдельных ЕПК по местам показа
A24: Вывод Head of PPC
A25: Бюджет канала — 1 000 000 ₽/мес без НДС, это база для ДРР. AOV 4 250 ₽ взял с витрины kids/boys, не из 1С — это допущение, не факт кабинета. Цель одна: «Покупка на сайте», автостратегии по умолчанию. Поиск и РСЯ в одной ЕПК не смешиваю — иначе не прочитаем аукцион и CR. Жёлтые ячейки здесь и на «Инструментах» — единственные входы модели.

Sheet Инструменты
A1: Инструменты: 6 кампаний ЕПК и бенчмарки воронки
A2: Поиск и РСЯ в одной кампании не смешиваю: иначе не прочитаем аукцион и CR. 32% на категорийный поиск — основной спрос родителей. Бренд дешевле клика, его задача — забрать свой трафик, не растить охват. Доля × бюджет из Допущения!C7; CTR/CPC/CR — жёлтые входы.
A4: # | B4: Кампания | C4: Тип кампании | D4: Тип площадки | E4: Доп. инструменты | F4: Тип объявлений | G4: Стратегия | H4: Доля бюджета | I4: Бюджет/мес, ₽ | J4: CTR | K4: CPC, ₽ | L4: CR в покупку | M4: Клики/мес | N4: Покупки/мес
A5: 1 | B5: ECCO Kids · бренд · Поиск | C5: ЕПК | D5: Поиск | E5: ключи бренд / бренд+товар | F5: текстово-графические | G5: Максимум конверсий | H5: 0.18 | I5: =ROUND(Допущения!$C$7*H5,0) -> 180000 | J5: 0.1 | K5: 28 | L5: 0.065 | M5: =IF(K5=0,0,ROUND(I5/K5,0)) -> 6429 | N5: =ROUND(M5*L5,0) -> 418
A6: 2 | B6: ECCO Kids · категория boys · Поиск | C6: ЕПК | D6: Поиск | E6: ключи категория kids/boys/кроссовки | F6: текстово-графические | G6: Максимум конверсий | H6: 0.32 | I6: =ROUND(Допущения!$C$7*H6,0) -> 320000 | J6: 0.045 | K6: 48 | L6: 0.038 | M6: =IF(K6=0,0,ROUND(I6/K6,0)) -> 6667 | N6: =ROUND(M6*L6,0) -> 253
A7: 3 | B7: ECCO Kids · товарная галерея · Поиск | C7: ЕПК | D7: Поиск | E7: фид + товарные объявления | F7: товарные | G7: Максимум конверсий | H7: 0.15 | I7: =ROUND(Допущения!$C$7*H7,0) -> 150000 | J7: 0.07 | K7: 44 | L7: 0.045 | M7: =IF(K7=0,0,ROUND(I7/K7,0)) -> 3409 | N7: =ROUND(M7*L7,0) -> 153
A8: 4 | B8: ECCO Kids · интересы и ретаргетинг · РСЯ | C8: ЕПК | D8: РСЯ | E8: интересы (kids/fashion/родители) + ретаргетинг визитов/корзины | F8: графические + текстово-графические | G8: Максимум конверсий | H8: 0.2 | I8: =ROUND(Допущения!$C$7*H8,0) -> 200000 | J8: 0.008 | K8: 11 | L8: 0.025 | M8: =IF(K8=0,0,ROUND(I8/K8,0)) -> 18182 | N8: =ROUND(M8*L8,0) -> 455
A9: 5 | B9: ECCO Kids · автотаргетинг · РСЯ | C9: ЕПК | D9: РСЯ | E9: автотаргетинг | F9: графические + текстово-графические | G9: Максимум кликов | H9: 0.1 | I9: =ROUND(Допущения!$C$7*H9,0) -> 100000 | J9: 0.008 | K9: 11 | L9: 0.015 | M9: =IF(K9=0,0,ROUND(I9/K9,0)) -> 9091 | N9: =ROUND(M9*L9,0) -> 136
A10: 6 | B10: ECCO Kids · защита бренда · РСЯ | C10: ЕПК | D10: РСЯ | E10: бренд в сетях | F10: графические + текстово-графические | G10: Максимум конверсий | H10: 0.05 | I10: =ROUND(Допущения!$C$7*H10,0) -> 50000 | J10: 0.008 | K10: 11 | L10: 0.025 | M10: =IF(K10=0,0,ROUND(I10/K10,0)) -> 4545 | N10: =ROUND(M10*L10,0) -> 114
B11: Итого / месяц | H11: =SUM(H5:H10) -> 1 | I11: =SUM(I5:I10) -> 1000000 | M11: =SUM(M5:M10) -> 48323 | N11: =SUM(N5:N10) -> 1529
A13: Проверка месяца (формулы)
A14: Выручка / мес | C14: =ROUND(N11*Допущения!C13,0) -> 6498250 | D14: ₽
A15: ДРР / мес | C15: =IF(C14=0,0,I11/C14) -> 0.15388759 | D15: %
A16: CPA / мес | C16: =IF(N11=0,0,I11/N11) -> 654.02224 | D16: ₽
A17: Контроль долей | C17: =IF(ABS(H11-1)<0.0001,"OK: 100%","Ошибка: сумма долей ≠ 100%") -> OK: 100%
A19: Комментарий к бенчам (наше усмотрение, не кабинет)
A20: Поиск: бренд CTR 10% / CPC 28 ₽ / CR 6,5% — дешевле и конвертит лучше категории boys (4,5% / 48 ₽ / 3,8%). Товарная галерея 7% / 44 ₽ / 4,5% — карточка поднимает CTR. РСЯ: CTR 0,8% и CPC 11 ₽ общие; CR 2,5% у интересов и защиты бренда, 1,5% у автотаргета «Максимум кликов». Кампанию «Поиск и РСЯ» в план не беру — грязный CR и аукцион.
A24: Вывод Head of PPC
A25: Итог месяца = сумма ROUND(доля × 1 000 000) — округление может дать ±2 ₽, это нормально. ДРР месяца держу в коридоре 15–25% — крутите жёлтые CTR/CPC/CR. Тип кампании везде ЕПК; «Поиск и РСЯ» как одна кампания отклонена — читаемость аукциона важнее. Стратегии из справки Директа; для e-com по умолчанию «Максимум конверсий» и цель «Покупка на сайте».

Sheet Медиаплан на год
A1: Медиаплан на год: 6 кампаний × 12 месяцев (все цифры — формулы)
A2: Сетка — 6 ЕПК × 12 месяцев. ДРР года = сумма расхода / сумма выручки, не среднее ДРР строк. Крутим жёлтые CTR/CPC/CR на «Инструментах», не копируем итоги. Показы = клики / CTR; клики = бюджет / CPC; покупки = клики × CR; выручка = покупки × AOV.
A4: Месяц | B4: Кампания | C4: Тип площадки | D4: Доп. инструменты | E4: Стратегия | F4: Бюджет, ₽ | G4: CTR | H4: CPC, ₽ | I4: Показы | J4: Клики | K4: CR | L4: Покупки | M4: Выручка, ₽ | N4: ДРР
A5: Сен 2026 | B5: =Инструменты!B5 -> ECCO Kids · бренд · Поиск | C5: =Инструменты!D5 -> Поиск | D5: =Инструменты!E5 -> ключи бренд / бренд+товар | E5: =Инструменты!G5 -> Максимум конверсий | F5: =Инструменты!I5 -> 180000 | G5: =Инструменты!J5 -> 0.1 | H5: =Инструменты!K5 -> 28 | I5: =IF(G5=0,0,ROUND(J5/G5,0)) -> 64290 | J5: =IF(H5=0,0,ROUND(F5/H5,0)) -> 6429 | K5: =Инструменты!L5 -> 0.065 | L5: =ROUND(J5*K5,0) -> 418 | M5: =ROUND(L5*Допущения!$C$13,0) -> 1776500 | N5: =IF(M5=0,0,F5/M5) -> 0.10132283
A6: Сен 2026 | B6: =Инструменты!B6 -> ECCO Kids · категория boys · Поиск | C6: =Инструменты!D6 -> Поиск | D6: =Инструменты!E6 -> ключи категория kids/boys/кроссовки | E6: =Инструменты!G6 -> Максимум конверсий | F6: =Инструменты!I6 -> 320000 | G6: =Инструменты!J6 -> 0.045 | H6: =Инструменты!K6 -> 48 | I6: =IF(G6=0,0,ROUND(J6/G6,0)) -> 148156 | J6: =IF(H6=0,0,ROUND(F6/H6,0)) -> 6667 | K6: =Инструменты!L6 -> 0.038 | L6: =ROUND(J6*K6,0) -> 253 | M6: =ROUND(L6*Допущения!$C$13,0) -> 1075250 | N6: =IF(M6=0,0,F6/M6) -> 0.29760521
A7: Сен 2026 | B7: =Инструменты!B7 -> ECCO Kids · товарная галерея · Поиск | C7: =Инструменты!D7 -> Поиск | D7: =Инструменты!E7 -> фид + товарные объявления | E7: =Инструменты!G7 -> Максимум конверсий | F7: =Инструменты!I7 -> 150000 | G7: =Инструменты!J7 -> 0.07 | H7: =Инструменты!K7 -> 44 | I7: =IF(G7=0,0,ROUND(J7/G7,0)) -> 48700 | J7: =IF(H7=0,0,ROUND(F7/H7,0)) -> 3409 | K7: =Инструменты!L7 -> 0.045 | L7: =ROUND(J7*K7,0) -> 153 | M7: =ROUND(L7*Допущения!$C$13,0) -> 650250 | N7: =IF(M7=0,0,F7/M7) -> 0.23068051
A8: Сен 2026 | B8: =Инструменты!B8 -> ECCO Kids · интересы и ретаргетинг · РСЯ | C8: =Инструменты!D8 -> РСЯ | D8: =Инструменты!E8 -> интересы (kids/fashion/родители) + ретаргетинг визитов/корзины | E8: =Инструменты!G8 -> Максимум конверсий | F8: =Инструменты!I8 -> 200000 | G8: =Инструменты!J8 -> 0.008 | H8: =Инструменты!K8 -> 11 | I8: =IF(G8=0,0,ROUND(J8/G8,0)) -> 2272750 | J8: =IF(H8=0,0,ROUND(F8/H8,0)) -> 18182 | K8: =Инструменты!L8 -> 0.025 | L8: =ROUND(J8*K8,0) -> 455 | M8: =ROUND(L8*Допущения!$C$13,0) -> 1933750 | N8: =IF(M8=0,0,F8/M8) -> 0.10342599
A9: Сен 2026 | B9: =Инструменты!B9 -> ECCO Kids · автотаргетинг · РСЯ | C9: =Инструменты!D9 -> РСЯ | D9: =Инструменты!E9 -> автотаргетинг | E9: =Инструменты!G9 -> Максимум кликов | F9: =Инструменты!I9 -> 100000 | G9: =Инструменты!J9 -> 0.008 | H9: =Инструменты!K9 -> 11 | I9: =IF(G9=0,0,ROUND(J9/G9,0)) -> 1136375 | J9: =IF(H9=0,0,ROUND(F9/H9,0)) -> 9091 | K9: =Инструменты!L9 -> 0.015 | L9: =ROUND(J9*K9,0) -> 136 | M9: =ROUND(L9*Допущения!$C$13,0) -> 578000 | N9: =IF(M9=0,0,F9/M9) -> 0.17301038
A10: Сен 2026 | B10: =Инструменты!B10 -> ECCO Kids · защита бренда · РСЯ | C10: =Инструменты!D10 -> РСЯ | D10: =Инструменты!E10 -> бренд в сетях | E10: =Инструменты!G10 -> Максимум конверсий | F10: =Инструменты!I10 -> 50000 | G10: =Инструменты!J10 -> 0.008 | H10: =Инструменты!K10 -> 11 | I10: =IF(G10=0,0,ROUND(J10/G10,0)) -> 568125 | J10: =IF(H10=0,0,ROUND(F10/H10,0)) -> 4545 | K10: =Инструменты!L10 -> 0.025 | L10: =ROUND(J10*K10,0) -> 114 | M10: =ROUND(L10*Допущения!$C$13,0) -> 484500 | N10: =IF(M10=0,0,F10/M10) -> 0.10319917
A11: Окт 2026 | B11: =Инструменты!B5 -> ECCO Kids · бренд · Поиск | C11: =Инструменты!D5 -> Поиск | D11: =Инструменты!E5 -> ключи бренд / бренд+товар | E11: =Инструменты!G5 -> Максимум конверсий | F11: =Инструменты!I5 -> 180000 | G11: =Инструменты!J5 -> 0.1 | H11: =Инструменты!K5 -> 28 | I11: =IF(G11=0,0,ROUND(J11/G11,0)) -> 64290 | J11: =IF(H11=0,0,ROUND(F11/H11,0)) -> 6429 | K11: =Инструменты!L5 -> 0.065 | L11: =ROUND(J11*K11,0) -> 418 | M11: =ROUND(L11*Допущения!$C$13,0) -> 1776500 | N11: =IF(M11=0,0,F11/M11) -> 0.10132283
A12: Окт 2026 | B12: =Инструменты!B6 -> ECCO Kids · категория boys · Поиск | C12: =Инструменты!D6 -> Поиск | D12: =Инструменты!E6 -> ключи категория kids/boys/кроссовки | E12: =Инструменты!G6 -> Максимум конверсий | F12: =Инструменты!I6 -> 320000 | G12: =Инструменты!J6 -> 0.045 | H12: =Инструменты!K6 -> 48 | I12: =IF(G12=0,0,ROUND(J12/G12,0)) -> 148156 | J12: =IF(H12=0,0,ROUND(F12/H12,0)) -> 6667 | K12: =Инструменты!L6 -> 0.038 | L12: =ROUND(J12*K12,0) -> 253 | M12: =ROUND(L12*Допущения!$C$13,0) -> 1075250 | N12: =IF(M12=0,0,F12/M12) -> 0.29760521
A13: Окт 2026 | B13: =Инструменты!B7 -> ECCO Kids · товарная галерея · Поиск | C13: =Инструменты!D7 -> Поиск | D13: =Инструменты!E7 -> фид + товарные объявления | E13: =Инструменты!G7 -> Максимум конверсий | F13: =Инструменты!I7 -> 150000 | G13: =Инструменты!J7 -> 0.07 | H13: =Инструменты!K7 -> 44 | I13: =IF(G13=0,0,ROUND(J13/G13,0)) -> 48700 | J13: =IF(H13=0,0,ROUND(F13/H13,0)) -> 3409 | K13: =Инструменты!L7 -> 0.045 | L13: =ROUND(J13*K13,0) -> 153 | M13: =ROUND(L13*Допущения!$C$13,0) -> 650250 | N13: =IF(M13=0,0,F13/M13) -> 0.23068051
A14: Окт 2026 | B14: =Инструменты!B8 -> ECCO Kids · интересы и ретаргетинг · РСЯ | C14: =Инструменты!D8 -> РСЯ | D14: =Инструменты!E8 -> интересы (kids/fashion/родители) + ретаргетинг визитов/корзины | E14: =Инструменты!G8 -> Максимум конверсий | F14: =Инструменты!I8 -> 200000 | G14: =Инструменты!J8 -> 0.008 | H14: =Инструменты!K8 -> 11 | I14: =IF(G14=0,0,ROUND(J14/G14,0)) -> 2272750 | J14: =IF(H14=0,0,ROUND(F14/H14,0)) -> 18182 | K14: =Инструменты!L8 -> 0.025 | L14: =ROUND(J14*K14,0) -> 455 | M14: =ROUND(L14*Допущения!$C$13,0) -> 1933750 | N14: =IF(M14=0,0,F14/M14) -> 0.10342599
A15: Окт 2026 | B15: =Инструменты!B9 -> ECCO Kids · автотаргетинг · РСЯ | C15: =Инструменты!D9 -> РСЯ | D15: =Инструменты!E9 -> автотаргетинг | E15: =Инструменты!G9 -> Максимум кликов | F15: =Инструменты!I9 -> 100000 | G15: =Инструменты!J9 -> 0.008 | H15: =Инструменты!K9 -> 11 | I15: =IF(G15=0,0,ROUND(J15/G15,0)) -> 1136375 | J15: =IF(H15=0,0,ROUND(F15/H15,0)) -> 9091 | K15: =Инструменты!L9 -> 0.015 | L15: =ROUND(J15*K15,0) -> 136 | M15: =ROUND(L15*Допущения!$C$13,0) -> 578000 | N15: =IF(M15=0,0,F15/M15) -> 0.17301038
A16: Окт 2026 | B16: =Инструменты!B10 -> ECCO Kids · защита бренда · РСЯ | C16: =Инструменты!D10 -> РСЯ | D16: =Инструменты!E10 -> бренд в сетях | E16: =Инструменты!G10 -> Максимум конверсий | F16: =Инструменты!I10 -> 50000 | G16: =Инструменты!J10 -> 0.008 | H16: =Инструменты!K10 -> 11 | I16: =IF(G16=0,0,ROUND(J16/G16,0)) -> 568125 | J16: =IF(H16=0,0,ROUND(F16/H16,0)) -> 4545 | K16: =Инструменты!L10 -> 0.025 | L16: =ROUND(J16*K16,0) -> 114 | M16: =ROUND(L16*Допущения!$C$13,0) -> 484500 | N16: =IF(M16=0,0,F16/M16) -> 0.10319917
A17: Ноя 2026 | B17: =Инструменты!B5 -> ECCO Kids · бренд · Поиск | C17: =Инструменты!D5 -> Поиск | D17: =Инструменты!E5 -> ключи бренд / бренд+товар | E17: =Инструменты!G5 -> Максимум конверсий | F17: =Инструменты!I5 -> 180000 | G17: =Инструменты!J5 -> 0.1 | H17: =Инструменты!K5 -> 28 | I17: =IF(G17=0,0,ROUND(J17/G17,0)) -> 64290 | J17: =IF(H17=0,0,ROUND(F17/H17,0)) -> 6429 | K17: =Инструменты!L5 -> 0.065 | L17: =ROUND(J17*K17,0) -> 418 | M17: =ROUND(L17*Допущения!$C$13,0) -> 1776500 | N17: =IF(M17=0,0,F17/M17) -> 0.10132283
A18: Ноя 2026 | B18: =Инструменты!B6 -> ECCO Kids · категория boys · Поиск | C18: =Инструменты!D6 -> Поиск | D18: =Инструменты!E6 -> ключи категория kids/boys/кроссовки | E18: =Инструменты!G6 -> Максимум конверсий | F18: =Инструменты!I6 -> 320000 | G18: =Инструменты!J6 -> 0.045 | H18: =Инструменты!K6 -> 48 | I18: =IF(G18=0,0,ROUND(J18/G18,0)) -> 148156 | J18: =IF(H18=0,0,ROUND(F18/H18,0)) -> 6667 | K18: =Инструменты!L6 -> 0.038 | L18: =ROUND(J18*K18,0) -> 253 | M18: =ROUND(L18*Допущения!$C$13,0) -> 1075250 | N18: =IF(M18=0,0,F18/M18) -> 0.29760521
A19: Ноя 2026 | B19: =Инструменты!B7 -> ECCO Kids · товарная галерея · Поиск | C19: =Инструменты!D7 -> Поиск | D19: =Инструменты!E7 -> фид + товарные объявления | E19: =Инструменты!G7 -> Максимум конверсий | F19: =Инструменты!I7 -> 150000 | G19: =Инструменты!J7 -> 0.07 | H19: =Инструменты!K7 -> 44 | I19: =IF(G19=0,0,ROUND(J19/G19,0)) -> 48700 | J19: =IF(H19=0,0,ROUND(F19/H19,0)) -> 3409 | K19: =Инструменты!L7 -> 0.045 | L19: =ROUND(J19*K19,0) -> 153 | M19: =ROUND(L19*Допущения!$C$13,0) -> 650250 | N19: =IF(M19=0,0,F19/M19) -> 0.23068051
A20: Ноя 2026 | B20: =Инструменты!B8 -> ECCO Kids · интересы и ретаргетинг · РСЯ | C20: =Инструменты!D8 -> РСЯ | D20: =Инструменты!E8 -> интересы (kids/fashion/родители) + ретаргетинг визитов/корзины | E20: =Инструменты!G8 -> Максимум конверсий | F20: =Инструменты!I8 -> 200000 | G20: =Инструменты!J8 -> 0.008 | H20: =Инструменты!K8 -> 11 | I20: =IF(G20=0,0,ROUND(J20/G20,0)) -> 2272750 | J20: =IF(H20=0,0,ROUND(F20/H20,0)) -> 18182 | K20: =Инструменты!L8 -> 0.025 | L20: =ROUND(J20*K20,0) -> 455 | M20: =ROUND(L20*Допущения!$C$13,0) -> 1933750 | N20: =IF(M20=0,0,F20/M20) -> 0.10342599
A21: Ноя 2026 | B21: =Инструменты!B9 -> ECCO Kids · автотаргетинг · РСЯ | C21: =Инструменты!D9 -> РСЯ | D21: =Инструменты!E9 -> автотаргетинг | E21: =Инструменты!G9 -> Максимум кликов | F21: =Инструменты!I9 -> 100000 | G21: =Инструменты!J9 -> 0.008 | H21: =Инструменты!K9 -> 11 | I21: =IF(G21=0,0,ROUND(J21/G21,0)) -> 1136375 | J21: =IF(H21=0,0,ROUND(F21/H21,0)) -> 9091 | K21: =Инструменты!L9 -> 0.015 | L21: =ROUND(J21*K21,0) -> 136 | M21: =ROUND(L21*Допущения!$C$13,0) -> 578000 | N21: =IF(M21=0,0,F21/M21) -> 0.17301038
A22: Ноя 2026 | B22: =Инструменты!B10 -> ECCO Kids · защита бренда · РСЯ | C22: =Инструменты!D10 -> РСЯ | D22: =Инструменты!E10 -> бренд в сетях | E22: =Инструменты!G10 -> Максимум конверсий | F22: =Инструменты!I10 -> 50000 | G22: =Инструменты!J10 -> 0.008 | H22: =Инструменты!K10 -> 11 | I22: =IF(G22=0,0,ROUND(J22/G22,0)) -> 568125 | J22: =IF(H22=0,0,ROUND(F22/H22,0)) -> 4545 | K22: =Инструменты!L10 -> 0.025 | L22: =ROUND(J22*K22,0) -> 114 | M22: =ROUND(L22*Допущения!$C$13,0) -> 484500 | N22: =IF(M22=0,0,F22/M22) -> 0.10319917
A23: Дек 2026 | B23: =Инструменты!B5 -> ECCO Kids · бренд · Поиск | C23: =Инструменты!D5 -> Поиск | D23: =Инструменты!E5 -> ключи бренд / бренд+товар | E23: =Инструменты!G5 -> Максимум конверсий | F23: =Инструменты!I5 -> 180000 | G23: =Инструменты!J5 -> 0.1 | H23: =Инструменты!K5 -> 28 | I23: =IF(G23=0,0,ROUND(J23/G23,0)) -> 64290 | J23: =IF(H23=0,0,ROUND(F23/H23,0)) -> 6429 | K23: =Инструменты!L5 -> 0.065 | L23: =ROUND(J23*K23,0) -> 418 | M23: =ROUND(L23*Допущения!$C$13,0) -> 1776500 | N23: =IF(M23=0,0,F23/M23) -> 0.10132283
A24: Дек 2026 | B24: =Инструменты!B6 -> ECCO Kids · категория boys · Поиск | C24: =Инструменты!D6 -> Поиск | D24: =Инструменты!E6 -> ключи категория kids/boys/кроссовки | E24: =Инструменты!G6 -> Максимум конверсий | F24: =Инструменты!I6 -> 320000 | G24: =Инструменты!J6 -> 0.045 | H24: =Инструменты!K6 -> 48 | I24: =IF(G24=0,0,ROUND(J24/G24,0)) -> 148156 | J24: =IF(H24=0,0,ROUND(F24/H24,0)) -> 6667 | K24: =Инструменты!L6 -> 0.038 | L24: =ROUND(J24*K24,0) -> 253 | M24: =ROUND(L24*Допущения!$C$13,0) -> 1075250 | N24: =IF(M24=0,0,F24/M24) -> 0.29760521
A25: Дек 2026 | B25: =Инструменты!B7 -> ECCO Kids · товарная галерея · Поиск | C25: =Инструменты!D7 -> Поиск | D25: =Инструменты!E7 -> фид + товарные объявления | E25: =Инструменты!G7 -> Максимум конверсий | F25: =Инструменты!I7 -> 150000 | G25: =Инструменты!J7 -> 0.07 | H25: =Инструменты!K7 -> 44 | I25: =IF(G25=0,0,ROUND(J25/G25,0)) -> 48700 | J25: =IF(H25=0,0,ROUND(F25/H25,0)) -> 3409 | K25: =Инструменты!L7 -> 0.045 | L25: =ROUND(J25*K25,0) -> 153 | M25: =ROUND(L25*Допущения!$C$13,0) -> 650250 | N25: =IF(M25=0,0,F25/M25) -> 0.23068051
A26: Дек 2026 | B26: =Инструменты!B8 -> ECCO Kids · интересы и ретаргетинг · РСЯ | C26: =Инструменты!D8 -> РСЯ | D26: =Инструменты!E8 -> интересы (kids/fashion/родители) + ретаргетинг визитов/корзины | E26: =Инструменты!G8 -> Максимум конверсий | F26: =Инструменты!I8 -> 200000 | G26: =Инструменты!J8 -> 0.008 | H26: =Инструменты!K8 -> 11 | I26: =IF(G26=0,0,ROUND(J26/G26,0)) -> 2272750 | J26: =IF(H26=0,0,ROUND(F26/H26,0)) -> 18182 | K26: =Инструменты!L8 -> 0.025 | L26: =ROUND(J26*K26,0) -> 455 | M26: =ROUND(L26*Допущения!$C$13,0) -> 1933750 | N26: =IF(M26=0,0,F26/M26) -> 0.10342599
A27: Дек 2026 | B27: =Инструменты!B9 -> ECCO Kids · автотаргетинг · РСЯ | C27: =Инструменты!D9 -> РСЯ | D27: =Инструменты!E9 -> автотаргетинг | E27: =Инструменты!G9 -> Максимум кликов | F27: =Инструменты!I9 -> 100000 | G27: =Инструменты!J9 -> 0.008 | H27: =Инструменты!K9 -> 11 | I27: =IF(G27=0,0,ROUND(J27/G27,0)) -> 1136375 | J27: =IF(H27=0,0,ROUND(F27/H27,0)) -> 9091 | K27: =Инструменты!L9 -> 0.015 | L27: =ROUND(J27*K27,0) -> 136 | M27: =ROUND(L27*Допущения!$C$13,0) -> 578000 | N27: =IF(M27=0,0,F27/M27) -> 0.17301038
A28: Дек 2026 | B28: =Инструменты!B10 -> ECCO Kids · защита бренда · РСЯ | C28: =Инструменты!D10 -> РСЯ | D28: =Инструменты!E10 -> бренд в сетях | E28: =Инструменты!G10 -> Максимум конверсий | F28: =Инструменты!I10 -> 50000 | G28: =Инструменты!J10 -> 0.008 | H28: =Инструменты!K10 -> 11 | I28: =IF(G28=0,0,ROUND(J28/G28,0)) -> 568125 | J28: =IF(H28=0,0,ROUND(F28/H28,0)) -> 4545 | K28: =Инструменты!L10 -> 0.025 | L28: =ROUND(J28*K28,0) -> 114 | M28: =ROUND(L28*Допущения!$C$13,0) -> 484500 | N28: =IF(M28=0,0,F28/M28) -> 0.10319917
A29: Янв 2027 | B29: =Инструменты!B5 -> ECCO Kids · бренд · Поиск | C29: =Инструменты!D5 -> Поиск | D29: =Инструменты!E5 -> ключи бренд / бренд+товар | E29: =Инструменты!G5 -> Максимум конверсий | F29: =Инструменты!I5 -> 180000 | G29: =Инструменты!J5 -> 0.1 | H29: =Инструменты!K5 -> 28 | I29: =IF(G29=0,0,ROUND(J29/G29,0)) -> 64290 | J29: =IF(H29=0,0,ROUND(F29/H29,0)) -> 6429 | K29: =Инструменты!L5 -> 0.065 | L29: =ROUND(J29*K29,0) -> 418 | M29: =ROUND(L29*Допущения!$C$13,0) -> 1776500 | N29: =IF(M29=0,0,F29/M29) -> 0.10132283
A30: Янв 2027 | B30: =Инструменты!B6 -> ECCO Kids · категория boys · Поиск | C30: =Инструменты!D6 -> Поиск | D30: =Инструменты!E6 -> ключи категория kids/boys/кроссовки | E30: =Инструменты!G6 -> Максимум конверсий | F30: =Инструменты!I6 -> 320000 | G30: =Инструменты!J6 -> 0.045 | H30: =Инструменты!K6 -> 48 | I30: =IF(G30=0,0,ROUND(J30/G30,0)) -> 148156 | J30: =IF(H30=0,0,ROUND(F30/H30,0)) -> 6667 | K30: =Инструменты!L6 -> 0.038 | L30: =ROUND(J30*K30,0) -> 253 | M30: =ROUND(L30*Допущения!$C$13,0) -> 1075250 | N30: =IF(M30=0,0,F30/M30) -> 0.29760521
A31: Янв 2027 | B31: =Инструменты!B7 -> ECCO Kids · товарная галерея · Поиск | C31: =Инструменты!D7 -> Поиск | D31: =Инструменты!E7 -> фид + товарные объявления | E31: =Инструменты!G7 -> Максимум конверсий | F31: =Инструменты!I7 -> 150000 | G31: =Инструменты!J7 -> 0.07 | H31: =Инструменты!K7 -> 44 | I31: =IF(G31=0,0,ROUND(J31/G31,0)) -> 48700 | J31: =IF(H31=0,0,ROUND(F31/H31,0)) -> 3409 | K31: =Инструменты!L7 -> 0.045 | L31: =ROUND(J31*K31,0) -> 153 | M31: =ROUND(L31*Допущения!$C$13,0) -> 650250 | N31: =IF(M31=0,0,F31/M31) -> 0.23068051
A32: Янв 2027 | B32: =Инструменты!B8 -> ECCO Kids · интересы и ретаргетинг · РСЯ | C32: =Инструменты!D8 -> РСЯ | D32: =Инструменты!E8 -> интересы (kids/fashion/родители) + ретаргетинг визитов/корзины | E32: =Инструменты!G8 -> Максимум конверсий | F32: =Инструменты!I8 -> 200000 | G32: =Инструменты!J8 -> 0.008 | H32: =Инструменты!K8 -> 11 | I32: =IF(G32=0,0,ROUND(J32/G32,0)) -> 2272750 | J32: =IF(H32=0,0,ROUND(F32/H32,0)) -> 18182 | K32: =Инструменты!L8 -> 0.025 | L32: =ROUND(J32*K32,0) -> 455 | M32: =ROUND(L32*Допущения!$C$13,0) -> 1933750 | N32: =IF(M32=0,0,F32/M32) -> 0.10342599
A33: Янв 2027 | B33: =Инструменты!B9 -> ECCO Kids · автотаргетинг · РСЯ | C33: =Инструменты!D9 -> РСЯ | D33: =Инструменты!E9 -> автотаргетинг | E33: =Инструменты!G9 -> Максимум кликов | F33: =Инструменты!I9 -> 100000 | G33: =Инструменты!J9 -> 0.008 | H33: =Инструменты!K9 -> 11 | I33: =IF(G33=0,0,ROUND(J33/G33,0)) -> 1136375 | J33: =IF(H33=0,0,ROUND(F33/H33,0)) -> 9091 | K33: =Инструменты!L9 -> 0.015 | L33: =ROUND(J33*K33,0) -> 136 | M33: =ROUND(L33*Допущения!$C$13,0) -> 578000 | N33: =IF(M33=0,0,F33/M33) -> 0.17301038
A34: Янв 2027 | B34: =Инструменты!B10 -> ECCO Kids · защита бренда · РСЯ | C34: =Инструменты!D10 -> РСЯ | D34: =Инструменты!E10 -> бренд в сетях | E34: =Инструменты!G10 -> Максимум конверсий | F34: =Инструменты!I10 -> 50000 | G34: =Инструменты!J10 -> 0.008 | H34: =Инструменты!K10 -> 11 | I34: =IF(G34=0,0,ROUND(J34/G34,0)) -> 568125 | J34: =IF(H34=0,0,ROUND(F34/H34,0)) -> 4545 | K34: =Инструменты!L10 -> 0.025 | L34: =ROUND(J34*K34,0) -> 114 | M34: =ROUND(L34*Допущения!$C$13,0) -> 484500 | N34: =IF(M34=0,0,F34/M34) -> 0.10319917
A35: Фев 2027 | B35: =Инструменты!B5 -> ECCO Kids · бренд · Поиск | C35: =Инструменты!D5 -> Поиск | D35: =Инструменты!E5 -> ключи бренд / бренд+товар | E35: =Инструменты!G5 -> Максимум конверсий | F35: =Инструменты!I5 -> 180000 | G35: =Инструменты!J5 -> 0.1 | H35: =Инструменты!K5 -> 28 | I35: =IF(G35=0,0,ROUND(J35/G35,0)) -> 64290 | J35: =IF(H35=0,0,ROUND(F35/H35,0)) -> 6429 | K35: =Инструменты!L5 -> 0.065 | L35: =ROUND(J35*K35,0) -> 418 | M35: =ROUND(L35*Допущения!$C$13,0) -> 1776500 | N35: =IF(M35=0,0,F35/M35) -> 0.10132283
A36: Фев 2027 | B36: =Инструменты!B6 -> ECCO Kids · категория boys · Поиск | C36: =Инструменты!D6 -> Поиск | D36: =Инструменты!E6 -> ключи категория kids/boys/кроссовки | E36: =Инструменты!G6 -> Максимум конверсий | F36: =Инструменты!I6 -> 320000 | G36: =Инструменты!J6 -> 0.045 | H36: =Инструменты!K6 -> 48 | I36: =IF(G36=0,0,ROUND(J36/G36,0)) -> 148156 | J36: =IF(H36=0,0,ROUND(F36/H36,0)) -> 6667 | K36: =Инструменты!L6 -> 0.038 | L36: =ROUND(J36*K36,0) -> 253 | M36: =ROUND(L36*Допущения!$C$13,0) -> 1075250 | N36: =IF(M36=0,0,F36/M36) -> 0.29760521
A37: Фев 2027 | B37: =Инструменты!B7 -> ECCO Kids · товарная галерея · Поиск | C37: =Инструменты!D7 -> Поиск | D37: =Инструменты!E7 -> фид + товарные объявления | E37: =Инструменты!G7 -> Максимум конверсий | F37: =Инструменты!I7 -> 150000 | G37: =Инструменты!J7 -> 0.07 | H37: =Инструменты!K7 -> 44 | I37: =IF(G37=0,0,ROUND(J37/G37,0)) -> 48700 | J37: =IF(H37=0,0,ROUND(F37/H37,0)) -> 3409 | K37: =Инструменты!L7 -> 0.045 | L37: =ROUND(J37*K37,0) -> 153 | M37: =ROUND(L37*Допущения!$C$13,0) -> 650250 | N37: =IF(M37=0,0,F37/M37) -> 0.23068051
A38: Фев 2027 | B38: =Инструменты!B8 -> ECCO Kids · интересы и ретаргетинг · РСЯ | C38: =Инструменты!D8 -> РСЯ | D38: =Инструменты!E8 -> интересы (kids/fashion/родители) + ретаргетинг визитов/корзины | E38: =Инструменты!G8 -> Максимум конверсий | F38: =Инструменты!I8 -> 200000 | G38: =Инструменты!J8 -> 0.008 | H38: =Инструменты!K8 -> 11 | I38: =IF(G38=0,0,ROUND(J38/G38,0)) -> 2272750 | J38: =IF(H38=0,0,ROUND(F38/H38,0)) -> 18182 | K38: =Инструменты!L8 -> 0.025 | L38: =ROUND(J38*K38,0) -> 455 | M38: =ROUND(L38*Допущения!$C$13,0) -> 1933750 | N38: =IF(M38=0,0,F38/M38) -> 0.10342599
A39: Фев 2027 | B39: =Инструменты!B9 -> ECCO Kids · автотаргетинг · РСЯ | C39: =Инструменты!D9 -> РСЯ | D39: =Инструменты!E9 -> автотаргетинг | E39: =Инструменты!G9 -> Максимум кликов | F39: =Инструменты!I9 -> 100000 | G39: =Инструменты!J9 -> 0.008 | H39: =Инструменты!K9 -> 11 | I39: =IF(G39=0,0,ROUND(J39/G39,0)) -> 1136375 | J39: =IF(H39=0,0,ROUND(F39/H39,0)) -> 9091 | K39: =Инструменты!L9 -> 0.015 | L39: =ROUND(J39*K39,0) -> 136 | M39: =ROUND(L39*Допущения!$C$13,0) -> 578000 | N39: =IF(M39=0,0,F39/M39) -> 0.17301038
A40: Фев 2027 | B40: =Инструменты!B10 -> ECCO Kids · защита бренда · РСЯ | C40: =Инструменты!D10 -> РСЯ | D40: =Инструменты!E10 -> бренд в сетях | E40: =Инструменты!G10 -> Максимум конверсий | F40: =Инструменты!I10 -> 50000 | G40: =Инструменты!J10 -> 0.008 | H40: =Инструменты!K10 -> 11 | I40: =IF(G40=0,0,ROUND(J40/G40,0)) -> 568125 | J40: =IF(H40=0,0,ROUND(F40/H40,0)) -> 4545 | K40: =Инструменты!L10 -> 0.025 | L40: =ROUND(J40*K40,0) -> 114 | M40: =ROUND(L40*Допущения!$C$13,0) -> 484500 | N40: =IF(M40=0,0,F40/M40) -> 0.10319917
A41: Мар 2027 | B41: =Инструменты!B5 -> ECCO Kids · бренд · Поиск | C41: =Инструменты!D5 -> Поиск | D41: =Инструменты!E5 -> ключи бренд / бренд+товар | E41: =Инструменты!G5 -> Максимум конверсий | F41: =Инструменты!I5 -> 180000 | G41: =Инструменты!J5 -> 0.1 | H41: =Инструменты!K5 -> 28 | I41: =IF(G41=0,0,ROUND(J41/G41,0)) -> 64290 | J41: =IF(H41=0,0,ROUND(F41/H41,0)) -> 6429 | K41: =Инструменты!L5 -> 0.065 | L41: =ROUND(J41*K41,0) -> 418 | M41: =ROUND(L41*Допущения!$C$13,0) -> 1776500 | N41: =IF(M41=0,0,F41/M41) -> 0.10132283
...

Sheet Сводка по месяцам
A1: Сводка по месяцам: SUMIF с листа «Медиаплан на год»
A2: Месяцы в модели равные, пока нет сезонного сдвига базы. ДРР месяца = сумма расхода / сумма выручки, не среднее ДРР кампаний.
A4: Месяц | B4: Расход, ₽ | C4: Показы | D4: Клики | E4: Покупки | F4: Выручка, ₽ | G4: ДРР | H4: CPA, ₽
A5: Сен 2026 | B5: =SUMIF('Медиаплан на год'!A:A,A5,'Медиаплан на год'!F:F) -> 1000000 | C5: =SUMIF('Медиаплан на год'!A:A,A5,'Медиаплан на год'!I:I) -> 4238396 | D5: =SUMIF('Медиаплан на год'!A:A,A5,'Медиаплан на год'!J:J) -> 48323 | E5: =SUMIF('Медиаплан на год'!A:A,A5,'Медиаплан на год'!L:L) -> 1529 | F5: =SUMIF('Медиаплан на год'!A:A,A5,'Медиаплан на год'!M:M) -> 6498250 | G5: =IF(F5=0,0,B5/F5) -> 0.15388759 | H5: =IF(E5=0,0,B5/E5) -> 654.02224
A6: Окт 2026 | B6: =SUMIF('Медиаплан на год'!A:A,A6,'Медиаплан на год'!F:F) -> 1000000 | C6: =SUMIF('Медиаплан на год'!A:A,A6,'Медиаплан на год'!I:I) -> 4238396 | D6: =SUMIF('Медиаплан на год'!A:A,A6,'Медиаплан на год'!J:J) -> 48323 | E6: =SUMIF('Медиаплан на год'!A:A,A6,'Медиаплан на год'!L:L) -> 1529 | F6: =SUMIF('Медиаплан на год'!A:A,A6,'Медиаплан на год'!M:M) -> 6498250 | G6: =IF(F6=0,0,B6/F6) -> 0.15388759 | H6: =IF(E6=0,0,B6/E6) -> 654.02224
A7: Ноя 2026 | B7: =SUMIF('Медиаплан на год'!A:A,A7,'Медиаплан на год'!F:F) -> 1000000 | C7: =SUMIF('Медиаплан на год'!A:A,A7,'Медиаплан на год'!I:I) -> 4238396 | D7: =SUMIF('Медиаплан на год'!A:A,A7,'Медиаплан на год'!J:J) -> 48323 | E7: =SUMIF('Медиаплан на год'!A:A,A7,'Медиаплан на год'!L:L) -> 1529 | F7: =SUMIF('Медиаплан на год'!A:A,A7,'Медиаплан на год'!M:M) -> 6498250 | G7: =IF(F7=0,0,B7/F7) -> 0.15388759 | H7: =IF(E7=0,0,B7/E7) -> 654.02224
A8: Дек 2026 | B8: =SUMIF('Медиаплан на год'!A:A,A8,'Медиаплан на год'!F:F) -> 1000000 | C8: =SUMIF('Медиаплан на год'!A:A,A8,'Медиаплан на год'!I:I) -> 4238396 | D8: =SUMIF('Медиаплан на год'!A:A,A8,'Медиаплан на год'!J:J) -> 48323 | E8: =SUMIF('Медиаплан на год'!A:A,A8,'Медиаплан на год'!L:L) -> 1529 | F8: =SUMIF('Медиаплан на год'!A:A,A8,'Медиаплан на год'!M:M) -> 6498250 | G8: =IF(F8=0,0,B8/F8) -> 0.15388759 | H8: =IF(E8=0,0,B8/E8) -> 654.02224
A9: Янв 2027 | B9: =SUMIF('Медиаплан на год'!A:A,A9,'Медиаплан на год'!F:F) -> 1000000 | C9: =SUMIF('Медиаплан на год'!A:A,A9,'Медиаплан на год'!I:I) -> 4238396 | D9: =SUMIF('Медиаплан на год'!A:A,A9,'Медиаплан на год'!J:J) -> 48323 | E9: =SUMIF('Медиаплан на год'!A:A,A9,'Медиаплан на год'!L:L) -> 1529 | F9: =SUMIF('Медиаплан на год'!A:A,A9,'Медиаплан на год'!M:M) -> 6498250 | G9: =IF(F9=0,0,B9/F9) -> 0.15388759 | H9: =IF(E9=0,0,B9/E9) -> 654.02224
A10: Фев 2027 | B10: =SUMIF('Медиаплан на год'!A:A,A10,'Медиаплан на год'!F:F) -> 1000000 | C10: =SUMIF('Медиаплан на год'!A:A,A10,'Медиаплан на год'!I:I) -> 4238396 | D10: =SUMIF('Медиаплан на год'!A:A,A10,'Медиаплан на год'!J:J) -> 48323 | E10: =SUMIF('Медиаплан на год'!A:A,A10,'Медиаплан на год'!L:L) -> 1529 | F10: =SUMIF('Медиаплан на год'!A:A,A10,'Медиаплан на год'!M:M) -> 6498250 | G10: =IF(F10=0,0,B10/F10) -> 0.15388759 | H10: =IF(E10=0,0,B10/E10) -> 654.02224
A11: Мар 2027 | B11: =SUMIF('Медиаплан на год'!A:A,A11,'Медиаплан на год'!F:F) -> 1000000 | C11: =SUMIF('Медиаплан на год'!A:A,A11,'Медиаплан на год'!I:I) -> 4238396 | D11: =SUMIF('Медиаплан на год'!A:A,A11,'Медиаплан на год'!J:J) -> 48323 | E11: =SUMIF('Медиаплан на год'!A:A,A11,'Медиаплан на год'!L:L) -> 1529 | F11: =SUMIF('Медиаплан на год'!A:A,A11,'Медиаплан на год'!M:M) -> 6498250 | G11: =IF(F11=0,0,B11/F11) -> 0.15388759 | H11: =IF(E11=0,0,B11/E11) -> 654.02224
A12: Апр 2027 | B12: =SUMIF('Медиаплан на год'!A:A,A12,'Медиаплан на год'!F:F) -> 1000000 | C12: =SUMIF('Медиаплан на год'!A:A,A12,'Медиаплан на год'!I:I) -> 4238396 | D12: =SUMIF('Медиаплан на год'!A:A,A12,'Медиаплан на год'!J:J) -> 48323 | E12: =SUMIF('Медиаплан на год'!A:A,A12,'Медиаплан на год'!L:L) -> 1529 | F12: =SUMIF('Медиаплан на год'!A:A,A12,'Медиаплан на год'!M:M) -> 6498250 | G12: =IF(F12=0,0,B12/F12) -> 0.15388759 | H12: =IF(E12=0,0,B12/E12) -> 654.02224
A13: Май 2027 | B13: =SUMIF('Медиаплан на год'!A:A,A13,'Медиаплан на год'!F:F) -> 1000000 | C13: =SUMIF('Медиаплан на год'!A:A,A13,'Медиаплан на год'!I:I) -> 4238396 | D13: =SUMIF('Медиаплан на год'!A:A,A13,'Медиаплан на год'!J:J) -> 48323 | E13: =SUMIF('Медиаплан на год'!A:A,A13,'Медиаплан на год'!L:L) -> 1529 | F13: =SUMIF('Медиаплан на год'!A:A,A13,'Медиаплан на год'!M:M) -> 6498250 | G13: =IF(F13=0,0,B13/F13) -> 0.15388759 | H13: =IF(E13=0,0,B13/E13) -> 654.02224
A14: Июн 2027 | B14: =SUMIF('Медиаплан на год'!A:A,A14,'Медиаплан на год'!F:F) -> 1000000 | C14: =SUMIF('Медиаплан на год'!A:A,A14,'Медиаплан на год'!I:I) -> 4238396 | D14: =SUMIF('Медиаплан на год'!A:A,A14,'Медиаплан на год'!J:J) -> 48323 | E14: =SUMIF('Медиаплан на год'!A:A,A14,'Медиаплан на год'!L:L) -> 1529 | F14: =SUMIF('Медиаплан на год'!A:A,A14,'Медиаплан на год'!M:M) -> 6498250 | G14: =IF(F14=0,0,B14/F14) -> 0.15388759 | H14: =IF(E14=0,0,B14/E14) -> 654.02224
A15: Июл 2027 | B15: =SUMIF('Медиаплан на год'!A:A,A15,'Медиаплан на год'!F:F) -> 1000000 | C15: =SUMIF('Медиаплан на год'!A:A,A15,'Медиаплан на год'!I:I) -> 4238396 | D15: =SUMIF('Медиаплан на год'!A:A,A15,'Медиаплан на год'!J:J) -> 48323 | E15: =SUMIF('Медиаплан на год'!A:A,A15,'Медиаплан на год'!L:L) -> 1529 | F15: =SUMIF('Медиаплан на год'!A:A,A15,'Медиаплан на год'!M:M) -> 6498250 | G15: =IF(F15=0,0,B15/F15) -> 0.15388759 | H15: =IF(E15=0,0,B15/E15) -> 654.02224
A16: Авг 2027 | B16: =SUMIF('Медиаплан на год'!A:A,A16,'Медиаплан на год'!F:F) -> 1000000 | C16: =SUMIF('Медиаплан на год'!A:A,A16,'Медиаплан на год'!I:I) -> 4238396 | D16: =SUMIF('Медиаплан на год'!A:A,A16,'Медиаплан на год'!J:J) -> 48323 | E16: =SUMIF('Медиаплан на год'!A:A,A16,'Медиаплан на год'!L:L) -> 1529 | F16: =SUMIF('Медиаплан на год'!A:A,A16,'Медиаплан на год'!M:M) -> 6498250 | G16: =IF(F16=0,0,B16/F16) -> 0.15388759 | H16: =IF(E16=0,0,B16/E16) -> 654.02224
A17: Итого год | B17: =SUM(B5:B16) -> 12000000 | C17: =SUM(C5:C16) -> 50860752 | D17: =SUM(D5:D16) -> 579876 | E17: =SUM(E5:E16) -> 18348 | F17: =SUM(F5:F16) -> 77979000 | G17: =IF(F17=0,0,B17/F17) -> 0.15388759 | H17: =IF(E17=0,0,B17/E17) -> 654.02224
A19: Вывод Head of PPC
A20: Месяцы одинаковые — модель без сезонности, расход и ДРР повторяются 12 раз. Если сентябрь/зима заберут долю — режем автотаргетинг РСЯ первым, бренд поиска не трогаем. ДРР = расход / выручка по сумме кампаний месяца. Выручка стабильно выше расхода при ДРР ~15% — это целевой коридор приёмки плана.

Sheet Сводка за год
A1: Сводка за год: инструменты и KPI (формулы с «Инструментов» × 12)
A2: Коридор ДРР 15–25% — условие приёмки плана. Годовая строка = месяц × 12; доли и бенчи не меняются.
A4: Кампания | B4: Тип площадки | C4: Доп. инструменты | D4: Доля | E4: Расход год, ₽ | F4: Клики год | G4: Покупки год | H4: Выручка год, ₽ | I4: ДРР | J4: CPA, ₽ | K4: Вклад в покупки
A5: =Инструменты!B5 -> ECCO Kids · бренд · Поиск | B5: =Инструменты!D5 -> Поиск | C5: =Инструменты!E5 -> ключи бренд / бренд+товар | D5: =Инструменты!H5 -> 0.18 | E5: =Инструменты!I5*Допущения!$C$9 -> 2160000 | F5: =Инструменты!M5*Допущения!$C$9 -> 77148 | G5: =Инструменты!N5*Допущения!$C$9 -> 5016 | H5: =ROUND(G5*Допущения!$C$13,0) -> 21318000 | I5: =IF(H5=0,0,E5/H5) -> 0.10132283 | J5: =IF(G5=0,0,E5/G5) -> 430.62201 | K5: =IF(G$11=0,0,G5/G$11) -> 0.27338129
A6: =Инструменты!B6 -> ECCO Kids · категория boys · Поиск | B6: =Инструменты!D6 -> Поиск | C6: =Инструменты!E6 -> ключи категория kids/boys/кроссовки | D6: =Инструменты!H6 -> 0.32 | E6: =Инструменты!I6*Допущения!$C$9 -> 3840000 | F6: =Инструменты!M6*Допущения!$C$9 -> 80004 | G6: =Инструменты!N6*Допущения!$C$9 -> 3036 | H6: =ROUND(G6*Допущения!$C$13,0) -> 12903000 | I6: =IF(H6=0,0,E6/H6) -> 0.29760521 | J6: =IF(G6=0,0,E6/G6) -> 1264.8221 | K6: =IF(G$11=0,0,G6/G$11) -> 0.16546763
A7: =Инструменты!B7 -> ECCO Kids · товарная галерея · Поиск | B7: =Инструменты!D7 -> Поиск | C7: =Инструменты!E7 -> фид + товарные объявления | D7: =Инструменты!H7 -> 0.15 | E7: =Инструменты!I7*Допущения!$C$9 -> 1800000 | F7: =Инструменты!M7*Допущения!$C$9 -> 40908 | G7: =Инструменты!N7*Допущения!$C$9 -> 1836 | H7: =ROUND(G7*Допущения!$C$13,0) -> 7803000 | I7: =IF(H7=0,0,E7/H7) -> 0.23068051 | J7: =IF(G7=0,0,E7/G7) -> 980.39216 | K7: =IF(G$11=0,0,G7/G$11) -> 0.1000654
A8: =Инструменты!B8 -> ECCO Kids · интересы и ретаргетинг · РСЯ | B8: =Инструменты!D8 -> РСЯ | C8: =Инструменты!E8 -> интересы (kids/fashion/родители) + ретаргетинг визитов/корзины | D8: =Инструменты!H8 -> 0.2 | E8: =Инструменты!I8*Допущения!$C$9 -> 2400000 | F8: =Инструменты!M8*Допущения!$C$9 -> 218184 | G8: =Инструменты!N8*Допущения!$C$9 -> 5460 | H8: =ROUND(G8*Допущения!$C$13,0) -> 23205000 | I8: =IF(H8=0,0,E8/H8) -> 0.10342599 | J8: =IF(G8=0,0,E8/G8) -> 439.56044 | K8: =IF(G$11=0,0,G8/G$11) -> 0.29758012
A9: =Инструменты!B9 -> ECCO Kids · автотаргетинг · РСЯ | B9: =Инструменты!D9 -> РСЯ | C9: =Инструменты!E9 -> автотаргетинг | D9: =Инструменты!H9 -> 0.1 | E9: =Инструменты!I9*Допущения!$C$9 -> 1200000 | F9: =Инструменты!M9*Допущения!$C$9 -> 109092 | G9: =Инструменты!N9*Допущения!$C$9 -> 1632 | H9: =ROUND(G9*Допущения!$C$13,0) -> 6936000 | I9: =IF(H9=0,0,E9/H9) -> 0.17301038 | J9: =IF(G9=0,0,E9/G9) -> 735.29412 | K9: =IF(G$11=0,0,G9/G$11) -> 0.088947024
A10: =Инструменты!B10 -> ECCO Kids · защита бренда · РСЯ | B10: =Инструменты!D10 -> РСЯ | C10: =Инструменты!E10 -> бренд в сетях | D10: =Инструменты!H10 -> 0.05 | E10: =Инструменты!I10*Допущения!$C$9 -> 600000 | F10: =Инструменты!M10*Допущения!$C$9 -> 54540 | G10: =Инструменты!N10*Допущения!$C$9 -> 1368 | H10: =ROUND(G10*Допущения!$C$13,0) -> 5814000 | I10: =IF(H10=0,0,E10/H10) -> 0.10319917 | J10: =IF(G10=0,0,E10/G10) -> 438.59649 | K10: =IF(G$11=0,0,G10/G$11) -> 0.074558535
A11: Итого год | D11: =SUM(D5:D10) -> 1 | E11: =SUM(E5:E10) -> 12000000 | F11: =SUM(F5:F10) -> 579876 | G11: =SUM(G5:G10) -> 18348 | H11: =SUM(H5:H10) -> 77979000 | I11: =IF(H11=0,0,E11/H11) -> 0.15388759 | J11: =IF(G11=0,0,E11/G11) -> 654.02224 | K11: =SUM(K5:K10) -> 1
A13: Сверка с сеткой года
A14: Расход (сводка) | B14: =E11 -> 12000000 | C14: Расход (сетка) | D14: ='Медиаплан на год'!F77 -> 12000000 | E14: Расхождение | F14: =B14-D14 -> 0
A15: Выручка (сводка) | B15: =H11 -> 77979000 | C15: Выручка (сетка) | D15: ='Медиаплан на год'!M77 -> 77979000 | E15: Расхождение | F15: =B15-D15 -> 0
A16: ДРР в коридоре 15–25% | B16: =IF(AND(I11>=0.15,I11<=0.25),"Да","Нет — проверьте бенчи") -> Да
A18: Вывод Head of PPC
A19: Коридор ДРР 15–25% — условие приёмки плана; ячейка B16 это проверяет. Категорийный поиск даёт объём покупок; автотаргетинг РСЯ — самый дорогой ДРР при малой доле, это плата за объём в сетях. Расхождение сводки и сетки — 0 ₽ при корректных формулах. После запуска сверяем факт CTR/CPC/CR и крутим жёлтые входы — это модель, не кабинет.
