Workbook

Sheet Параметры плана
A1: Параметры плана: ECCO Kids — медиаплан Яндекс Директ
A2: Бюджет и AOV — цифры для формул; ниже — условия, по которым собран сплит кампаний и воронка до покупки.
A4: Данные для расчёта
A5: Источник | B5: Параметр | C5: Значение | D5: Ед.
A6: из исходных данных | B6: Месячный бюджет без НДС | C6: 1000000 | D6: ₽
A7: информация с сайта | B7: Средний чек (AOV) | C7: 4250 | D7: ₽
A8: из исходных данных | B8: Горизонт планирования | C8: 12 | D8: мес
A10: Условия расчёта
A11: Источник | B11: Условие | C11: Значение
A12: из исходных данных | B12: Целевое действие | C12: Покупка на сайте (Метрика)
A13: из исходных данных | B13: KPI эффективности | C13: ДРР = расход без НДС / выручка
A14: из исходных данных | B14: Коридор ДРР | C14: 15–25%
A15: принимаем значение | B15: Распределение бюджета по месяцам | C15: Сезонные веса (таблица ниже): пики сен/окт и янв; лето ниже базы; год = 12 млн ₽ без НДС
A16: принимаем значение | B16: Места показа | C16: Поиск и РСЯ — отдельные ЕПК, не смешиваем
A17: принимаем значение | B17: Воронка | C17: Показы → клики → покупки → выручка
A19: Сезонность по месяцам
A20: Месяц | B20: Вес | C20: Бюджет канала, ₽
A21: Сен 2026 | B21: 1.15 | C21: =ROUND($C$6*B21,0)
A22: Окт 2026 | B22: 1.1 | C22: =ROUND($C$6*B22,0)
A23: Ноя 2026 | B23: 1.05 | C23: =ROUND($C$6*B23,0)
A24: Дек 2026 | B24: 1.05 | C24: =ROUND($C$6*B24,0)
A25: Янв 2027 | B25: 1.15 | C25: =ROUND($C$6*B25,0)
A26: Фев 2027 | B26: 1.05 | C26: =ROUND($C$6*B26,0)
A27: Мар 2027 | B27: 1 | C27: =ROUND($C$6*B27,0)
A28: Апр 2027 | B28: 0.95 | C28: =ROUND($C$6*B28,0)
A29: Май 2027 | B29: 0.9 | C29: =ROUND($C$6*B29,0)
A30: Июн 2027 | B30: 0.85 | C30: =ROUND($C$6*B30,0)
A31: Июл 2027 | B31: 0.8 | C31: =ROUND($C$6*B31,0)
A32: Авг 2027 | B32: 0.95 | C32: =ROUND($C$6*B32,0)
A33: Итого | B33: =SUM(B21:B32) | C33: =SUM(C21:C32)
A35: Комментарий к расчёту
A36: На листе разделены цифры, которые подставляются в формулы, и правила, по которым собран медиаплан. 1 000 000 ₽/мес без НДС — опорный месяц (вес 1,0); на сетке года к базовому расходу кампании умножаются сезонные веса из таблицы ниже — сумма весов 12, годовой расход канала 12 000 000 ₽. AOV 4 250 ₽ взяли с витрины kids/boys как рабочую оценку среднего чека: от него считается выручка и весь ДРР. Цель воронки — «Покупка на сайте»; KPI — ДРР в коридоре 15–25%. Пики сентябрь/октябрь (школа) и январь (зима) — усиливаем категорийный Поиск и товарную галерею, плюс интересы и ретаргетинг РСЯ; летом (июнь–июль) ниже базы — первым режем автотаргетинг РСЯ, бренд-Поиск и ретаргет не трогаем. Если после запуска средний чек или CR в кабинете расходятся с планом — правим параметры или бенчи на «Инструментах», а не пересчитываем вручную строки года.

Sheet Инструменты
A1: Инструменты: 6 кампаний ЕПК и бенчмарки воронки
A2: Поиск и РСЯ в одной кампании не смешиваю: иначе не прочитаем аукцион и CR. 32% на категорийный поиск — основной спрос родителей. Бренд дешевле клика, его задача — забрать свой трафик, не растить охват. Доля × бюджет из листа «Параметры плана» ('Параметры плана'!$C$6) — опорный месяц (вес 1,0); на сетке года к расходу кампании умножаются сезонные веса. CTR/CPC/CR — жёлтые входы.
A4: # | B4: Кампания | C4: Тип кампании | D4: Тип площадки | E4: Доп. инструменты | F4: Тип объявлений | G4: Стратегия | H4: Доля бюджета | I4: Бюджет/мес, ₽ | J4: CTR | K4: CPC, ₽ | L4: CR в покупку | M4: Клики/мес | N4: Покупки/мес
A5: 1 | B5: ECCO Kids · бренд · Поиск | C5: ЕПК | D5: Поиск | E5: ключи бренд / бренд+товар | F5: текстово-графические | G5: Максимум конверсий | H5: 0.18 | I5: =ROUND('Параметры плана'!$C$6*H5,0) | J5: 0.1 | K5: 28 | L5: 0.065 | M5: =IF(K5=0,0,ROUND(I5/K5,0)) | N5: =ROUND(M5*L5,0)
A6: 2 | B6: ECCO Kids · категория boys · Поиск | C6: ЕПК | D6: Поиск | E6: ключи категория kids/boys/кроссовки | F6: текстово-графические | G6: Максимум конверсий | H6: 0.32 | I6: =ROUND('Параметры плана'!$C$6*H6,0) | J6: 0.045 | K6: 48 | L6: 0.038 | M6: =IF(K6=0,0,ROUND(I6/K6,0)) | N6: =ROUND(M6*L6,0)
A7: 3 | B7: ECCO Kids · товарная галерея · Поиск | C7: ЕПК | D7: Поиск | E7: фид + товарные объявления | F7: товарные | G7: Максимум конверсий | H7: 0.15 | I7: =ROUND('Параметры плана'!$C$6*H7,0) | J7: 0.07 | K7: 44 | L7: 0.045 | M7: =IF(K7=0,0,ROUND(I7/K7,0)) | N7: =ROUND(M7*L7,0)
A8: 4 | B8: ECCO Kids · интересы и ретаргетинг · РСЯ | C8: ЕПК | D8: РСЯ | E8: интересы (kids/fashion/родители) + ретаргетинг визитов/корзины | F8: графические + текстово-графические | G8: Максимум конверсий | H8: 0.2 | I8: =ROUND('Параметры плана'!$C$6*H8,0) | J8: 0.008 | K8: 11 | L8: 0.025 | M8: =IF(K8=0,0,ROUND(I8/K8,0)) | N8: =ROUND(M8*L8,0)
A9: 5 | B9: ECCO Kids · автотаргетинг · РСЯ | C9: ЕПК | D9: РСЯ | E9: автотаргетинг | F9: графические + текстово-графические | G9: Максимум кликов | H9: 0.1 | I9: =ROUND('Параметры плана'!$C$6*H9,0) | J9: 0.008 | K9: 11 | L9: 0.015 | M9: =IF(K9=0,0,ROUND(I9/K9,0)) | N9: =ROUND(M9*L9,0)
A10: 6 | B10: ECCO Kids · защита бренда · РСЯ | C10: ЕПК | D10: РСЯ | E10: бренд в сетях | F10: графические + текстово-графические | G10: Максимум конверсий | H10: 0.05 | I10: =ROUND('Параметры плана'!$C$6*H10,0) | J10: 0.008 | K10: 11 | L10: 0.025 | M10: =IF(K10=0,0,ROUND(I10/K10,0)) | N10: =ROUND(M10*L10,0)
B11: Итого / месяц | H11: =SUM(H5:H10) | I11: =SUM(I5:I10) | M11: =SUM(M5:M10) | N11: =SUM(N5:N10)
A13: Проверка месяца (формулы)
A14: Выручка / мес | C14: =ROUND(N11*'Параметры плана'!$C$7,0) | D14: ₽
A15: ДРР / мес | C15: =IF(C14=0,0,I11/C14) | D15: %
A16: CPA / мес | C16: =IF(N11=0,0,I11/N11) | D16: ₽
A17: Контроль долей | C17: =IF(ABS(H11-1)<0.0001,"OK: 100%","Ошибка: сумма долей ≠ 100%")
A19: Обоснование сплита и расчёта
A20: Кампания | B20: Места показа | C20: Доля / расход | D20: Почему этот тип кампании и условие показа | E20: Почему такая доля бюджета | F20: Экономика месяца
A21: =B5 | B21: Поиск | C21: =TEXT(H5,"0%")&" ("&TEXT(I5,"#,##0")&" ₽/мес)" | D21: Тип: ЕПК, места показа только Поиск, объявления текстово-графические, стратегия «Максимум конверсий», цель Метрики «Покупка на сайте». Условие показа — ключи бренд и бренд+товар. Почему тип: бренд в Поиске — самый дешёвый и предсказуемый спрос. Смешивать с РСЯ нельзя: другой аукцион и другой CR. | E21: Почему 18% (180 000 ₽/мес): этого достаточно, чтобы забрать свой спрос, но не раздувать бренд сверх частотности. Основной объём категории должен жить в небренде. | F21: Экономика (допущение, не кабинет): CTR 10,0%, CPC 28 ₽ → ~6 429 кликов; CR 6,5% → ~418 покупок; CPA ≈ 431 ₽; выручка ≈ 1,78 млн ₽; ДРР ≈ 10%. Это якорь канала: низкий ДРР компенсирует более дорогой категорийный поиск.
A22: =B6 | B22: Поиск | C22: =TEXT(H6,"0%")&" ("&TEXT(I6,"#,##0")&" ₽/мес)" | D22: Тип: ЕПК, Поиск, ТГО, «Максимум конверсий», ключи категория kids/boys/кроссовки/детская обувь — спрос родителей, не бренд. Почему тип: без категорийного Поиска нет объёма покупок в e-com обуви. Товарные объявления сюда не кладу: фид и семантика — разные рычаги оптимизации. | E22: Почему 32% (320 000 ₽) — крупнейшая доля: это основной небренд-спрос. Меньше 25% — недобор категории; больше 40% — ДРР канала вылетает из коридора, потому что CPC 48 ₽ и CR 3,8% тяжелее бренда. | F22: Экономика: CTR 4,5%, CPC 48 ₽ → ~6 667 кликов; CR 3,8% → ~253 покупки; CPA ≈ 1 265 ₽; ДРР строки ≈ 30%. Строка «дорогая» сознательно: её тянет бренд и РСЯ-ретаргет с ДРР ~10%.
A23: =B7 | B23: Поиск | C23: =TEXT(H7,"0%")&" ("&TEXT(I7,"#,##0")&" ₽/мес)" | D23: Тип: ЕПК, Поиск, товарные объявления (фид), «Максимум конверсий». Не путать с типом кампании: ЕПК — кампания, товарное — тип объявления. Почему тип: карточка товара на Поиске поднимает CTR vs текст (7% vs 4,5%) и закрывает SKU kids/boys без отдельной «медийки». | E23: Почему 15% (150 000 ₽): фид должен получить статистику на обучение стратегии, но не съесть семантику. 10% мало для фида, 25% дублирует категорийный поиск. | F23: Экономика: CTR 7,0%, CPC 44 ₽ → ~3 409 кликов; CR 4,5% → ~153 покупки; CPA ≈ 980 ₽; ДРР ≈ 23% — середина между брендом и категорией.
A24: =B8 | B24: РСЯ | C24: =TEXT(H8,"0%")&" ("&TEXT(I8,"#,##0")&" ₽/мес)" | D24: Тип: ЕПК, места показа только РСЯ, графика + ТГО, «Максимум конверсий». Условие показа: интересы (kids/fashion/родители) + ретаргетинг визитов и корзины. Почему тип: сети закрывают тех, кто не ввёл запрос, и дожимают визит/корзину. Поиск сюда не мешаю. | E24: Почему 20% (200 000 ₽): e-com kids без ретаргета теряет догрев. Больше 25% РСЯ-интересов размывает ДРР: CTR сети 0,8%, конверсия холоднее Поиска. | F24: Экономика: CPC 11 ₽ → ~18 182 клика; CR 2,5% → ~455 покупок; CPA ≈ 440 ₽; ДРР ≈ 10%. Дешёвый клик + тёплый ретаргет — второй якорь ДРР после бренда.
A25: =B9 | B25: РСЯ | C25: =TEXT(H9,"0%")&" ("&TEXT(I9,"#,##0")&" ₽/мес)" | D25: Тип: ЕПК, РСЯ, автотаргетинг, «Максимум кликов» (не «Максимум конверсий»: автотаргету сначала нужен объём кликов, CR ниже). Почему тип: автотаргетинг расширяет охват, но условие показа система берёт сама — CR падает до 1,5%. Держу отдельно, чтобы не портить статистику интересов/ретаргета. | E25: Почему 10% (100 000 ₽): тестовый объём. Резать первым, если факт ДРР > 25%. Не поднимать, пока CR не догонит интересы. | F25: Экономика: CPC 11 ₽ → ~9 091 клик; CR 1,5% → ~136 покупок; CPA ≈ 735 ₽; ДРР ≈ 17%. Плата за объём в сетях.
A26: =B10 | B26: РСЯ | C26: =TEXT(H10,"0%")&" ("&TEXT(I10,"#,##0")&" ₽/мес)" | D26: Тип: ЕПК, РСЯ, бренд в сетях, «Максимум конверсий», графика + ТГО. Почему тип: защита бренда в РСЯ, чтобы конкурент не перехватывал показ по бренду вне Поиска. Не смешивать с бренд-Поиском. | E26: Почему 5% (50 000 ₽): частотность бренда в сетях ограничена. 10%+ — переплата за те же аукционы. | F26: Экономика: CPC 11 ₽ → ~4 545 кликов; CR 2,5% → ~114 покупок; CPA ≈ 439 ₽; ДРР ≈ 10%.
A28: Комментарий к расчёту
A29: Главное в сплите — два якоря с низким ДРР: бренд в Поиске и ретаргет в РСЯ. Они перекрывают «тяжёлую» категорийную строку с CPC 48 ₽ — без этого микс не проходит коридор 15–25%. Категория 32% — не жадность, а единственный источник объёма небренда; резать её первой нельзя. Автотаргетинг держу отдельно и с «Максимум кликов»: это буфер на объём, его снимаем при первом признаке просадки CR, не трогая бренд и ретаргет. Таблица обоснования выше — логика долей; цифры месяца пересчитаются сами при смене жёлтых бенчей.

Sheet Медиаплан на год
A1: Медиаплан на год: 6 кампаний × 12 месяцев (все цифры — формулы)
A2: Сетка — 6 ЕПК × 12 месяцев; бюджет строки = база «Инструментов» × сезонный вес с «Параметры плана» ('Параметры плана'!$A$21:$B$32). ДРР года = сумма расхода / сумма выручки, не среднее ДРР строк. Крутим жёлтые CTR/CPC/CR на «Инструментах», не копируем итоги. Показы = клики / CTR; клики = бюджет / CPC; покупки = клики × CR; выручка = покупки × AOV.
A4: Месяц | B4: Кампания | C4: Тип площадки | D4: Доп. инструменты | E4: Стратегия | F4: Бюджет, ₽ | G4: CTR | H4: CPC, ₽ | I4: Показы | J4: Клики | K4: CR | L4: Покупки | M4: Выручка, ₽ | N4: ДРР
A5: Сен 2026 | B5: =Инструменты!B5 | C5: =Инструменты!D5 | D5: =Инструменты!E5 | E5: =Инструменты!G5 | F5: =ROUND(Инструменты!I5*VLOOKUP(A5,'Параметры плана'!$A$21:$B$32,2,FALSE),0) | G5: =Инструменты!J5 | H5: =Инструменты!K5 | I5: =IF(G5=0,0,ROUND(J5/G5,0)) | J5: =IF(H5=0,0,ROUND(F5/H5,0)) | K5: =Инструменты!L5 | L5: =ROUND(J5*K5,0) | M5: =ROUND(L5*'Параметры плана'!$C$7,0) | N5: =IF(M5=0,0,F5/M5)
A6: Сен 2026 | B6: =Инструменты!B6 | C6: =Инструменты!D6 | D6: =Инструменты!E6 | E6: =Инструменты!G6 | F6: =ROUND(Инструменты!I6*VLOOKUP(A6,'Параметры плана'!$A$21:$B$32,2,FALSE),0) | G6: =Инструменты!J6 | H6: =Инструменты!K6 | I6: =IF(G6=0,0,ROUND(J6/G6,0)) | J6: =IF(H6=0,0,ROUND(F6/H6,0)) | K6: =Инструменты!L6 | L6: =ROUND(J6*K6,0) | M6: =ROUND(L6*'Параметры плана'!$C$7,0) | N6: =IF(M6=0,0,F6/M6)
A7: Сен 2026 | B7: =Инструменты!B7 | C7: =Инструменты!D7 | D7: =Инструменты!E7 | E7: =Инструменты!G7 | F7: =ROUND(Инструменты!I7*VLOOKUP(A7,'Параметры плана'!$A$21:$B$32,2,FALSE),0) | G7: =Инструменты!J7 | H7: =Инструменты!K7 | I7: =IF(G7=0,0,ROUND(J7/G7,0)) | J7: =IF(H7=0,0,ROUND(F7/H7,0)) | K7: =Инструменты!L7 | L7: =ROUND(J7*K7,0) | M7: =ROUND(L7*'Параметры плана'!$C$7,0) | N7: =IF(M7=0,0,F7/M7)
A8: Сен 2026 | B8: =Инструменты!B8 | C8: =Инструменты!D8 | D8: =Инструменты!E8 | E8: =Инструменты!G8 | F8: =ROUND(Инструменты!I8*VLOOKUP(A8,'Параметры плана'!$A$21:$B$32,2,FALSE),0) | G8: =Инструменты!J8 | H8: =Инструменты!K8 | I8: =IF(G8=0,0,ROUND(J8/G8,0)) | J8: =IF(H8=0,0,ROUND(F8/H8,0)) | K8: =Инструменты!L8 | L8: =ROUND(J8*K8,0) | M8: =ROUND(L8*'Параметры плана'!$C$7,0) | N8: =IF(M8=0,0,F8/M8)
A9: Сен 2026 | B9: =Инструменты!B9 | C9: =Инструменты!D9 | D9: =Инструменты!E9 | E9: =Инструменты!G9 | F9: =ROUND(Инструменты!I9*VLOOKUP(A9,'Параметры плана'!$A$21:$B$32,2,FALSE),0) | G9: =Инструменты!J9 | H9: =Инструменты!K9 | I9: =IF(G9=0,0,ROUND(J9/G9,0)) | J9: =IF(H9=0,0,ROUND(F9/H9,0)) | K9: =Инструменты!L9 | L9: =ROUND(J9*K9,0) | M9: =ROUND(L9*'Параметры плана'!$C$7,0) | N9: =IF(M9=0,0,F9/M9)
A10: Сен 2026 | B10: =Инструменты!B10 | C10: =Инструменты!D10 | D10: =Инструменты!E10 | E10: =Инструменты!G10 | F10: =ROUND(Инструменты!I10*VLOOKUP(A10,'Параметры плана'!$A$21:$B$32,2,FALSE),0) | G10: =Инструменты!J10 | H10: =Инструменты!K10 | I10: =IF(G10=0,0,ROUND(J10/G10,0)) | J10: =IF(H10=0,0,ROUND(F10/H10,0)) | K10: =Инструменты!L10 | L10: =ROUND(J10*K10,0) | M10: =ROUND(L10*'Параметры плана'!$C$7,0) | N10: =IF(M10=0,0,F10/M10)
A11: Окт 2026 | B11: =Инструменты!B5 | C11: =Инструменты!D5 | D11: =Инструменты!E5 | E11: =Инструменты!G5 | F11: =ROUND(Инструменты!I5*VLOOKUP(A11,'Параметры плана'!$A$21:$B$32,2,FALSE),0) | G11: =Инструменты!J5 | H11: =Инструменты!K5 | I11: =IF(G11=0,0,ROUND(J11/G11,0)) | J11: =IF(H11=0,0,ROUND(F11/H11,0)) | K11: =Инструменты!L5 | L11: =ROUND(J11*K11,0) | M11: =ROUND(L11*'Параметры плана'!$C$7,0) | N11: =IF(M11=0,0,F11/M11)
A12: Окт 2026 | B12: =Инструменты!B6 | C12: =Инструменты!D6 | D12: =Инструменты!E6 | E12: =Инструменты!G6 | F12: =ROUND(Инструменты!I6*VLOOKUP(A12,'Параметры плана'!$A$21:$B$32,2,FALSE),0) | G12: =Инструменты!J6 | H12: =Инструменты!K6 | I12: =IF(G12=0,0,ROUND(J12/G12,0)) | J12: =IF(H12=0,0,ROUND(F12/H12,0)) | K12: =Инструменты!L6 | L12: =ROUND(J12*K12,0) | M12: =ROUND(L12*'Параметры плана'!$C$7,0) | N12: =IF(M12=0,0,F12/M12)
A13: Окт 2026 | B13: =Инструменты!B7 | C13: =Инструменты!D7 | D13: =Инструменты!E7 | E13: =Инструменты!G7 | F13: =ROUND(Инструменты!I7*VLOOKUP(A13,'Параметры плана'!$A$21:$B$32,2,FALSE),0) | G13: =Инструменты!J7 | H13: =Инструменты!K7 | I13: =IF(G13=0,0,ROUND(J13/G13,0)) | J13: =IF(H13=0,0,ROUND(F13/H13,0)) | K13: =Инструменты!L7 | L13: =ROUND(J13*K13,0) | M13: =ROUND(L13*'Параметры плана'!$C$7,0) | N13: =IF(M13=0,0,F13/M13)
A14: Окт 2026 | B14: =Инструменты!B8 | C14: =Инструменты!D8 | D14: =Инструменты!E8 | E14: =Инструменты!G8 | F14: =ROUND(Инструменты!I8*VLOOKUP(A14,'Параметры плана'!$A$21:$B$32,2,FALSE),0) | G14: =Инструменты!J8 | H14: =Инструменты!K8 | I14: =IF(G14=0,0,ROUND(J14/G14,0)) | J14: =IF(H14=0,0,ROUND(F14/H14,0)) | K14: =Инструменты!L8 | L14: =ROUND(J14*K14,0) | M14: =ROUND(L14*'Параметры плана'!$C$7,0) | N14: =IF(M14=0,0,F14/M14)
A15: Окт 2026 | B15: =Инструменты!B9 | C15: =Инструменты!D9 | D15: =Инструменты!E9 | E15: =Инструменты!G9 | F15: =ROUND(Инструменты!I9*VLOOKUP(A15,'Параметры плана'!$A$21:$B$32,2,FALSE),0) | G15: =Инструменты!J9 | H15: =Инструменты!K9 | I15: =IF(G15=0,0,ROUND(J15/G15,0)) | J15: =IF(H15=0,0,ROUND(F15/H15,0)) | K15: =Инструменты!L9 | L15: =ROUND(J15*K15,0) | M15: =ROUND(L15*'Параметры плана'!$C$7,0) | N15: =IF(M15=0,0,F15/M15)
A16: Окт 2026 | B16: =Инструменты!B10 | C16: =Инструменты!D10 | D16: =Инструменты!E10 | E16: =Инструменты!G10 | F16: =ROUND(Инструменты!I10*VLOOKUP(A16,'Параметры плана'!$A$21:$B$32,2,FALSE),0) | G16: =Инструменты!J10 | H16: =Инструменты!K10 | I16: =IF(G16=0,0,ROUND(J16/G16,0)) | J16: =IF(H16=0,0,ROUND(F16/H16,0)) | K16: =Инструменты!L10 | L16: =ROUND(J16*K16,0) | M16: =ROUND(L16*'Параметры плана'!$C$7,0) | N16: =IF(M16=0,0,F16/M16)
A17: Ноя 2026 | B17: =Инструменты!B5 | C17: =Инструменты!D5 | D17: =Инструменты!E5 | E17: =Инструменты!G5 | F17: =ROUND(Инструменты!I5*VLOOKUP(A17,'Параметры плана'!$A$21:$B$32,2,FALSE),0) | G17: =Инструменты!J5 | H17: =Инструменты!K5 | I17: =IF(G17=0,0,ROUND(J17/G17,0)) | J17: =IF(H17=0,0,ROUND(F17/H17,0)) | K17: =Инструменты!L5 | L17: =ROUND(J17*K17,0) | M17: =ROUND(L17*'Параметры плана'!$C$7,0) | N17: =IF(M17=0,0,F17/M17)
A18: Ноя 2026 | B18: =Инструменты!B6 | C18: =Инструменты!D6 | D18: =Инструменты!E6 | E18: =Инструменты!G6 | F18: =ROUND(Инструменты!I6*VLOOKUP(A18,'Параметры плана'!$A$21:$B$32,2,FALSE),0) | G18: =Инструменты!J6 | H18: =Инструменты!K6 | I18: =IF(G18=0,0,ROUND(J18/G18,0)) | J18: =IF(H18=0,0,ROUND(F18/H18,0)) | K18: =Инструменты!L6 | L18: =ROUND(J18*K18,0) | M18: =ROUND(L18*'Параметры плана'!$C$7,0) | N18: =IF(M18=0,0,F18/M18)
A19: Ноя 2026 | B19: =Инструменты!B7 | C19: =Инструменты!D7 | D19: =Инструменты!E7 | E19: =Инструменты!G7 | F19: =ROUND(Инструменты!I7*VLOOKUP(A19,'Параметры плана'!$A$21:$B$32,2,FALSE),0) | G19: =Инструменты!J7 | H19: =Инструменты!K7 | I19: =IF(G19=0,0,ROUND(J19/G19,0)) | J19: =IF(H19=0,0,ROUND(F19/H19,0)) | K19: =Инструменты!L7 | L19: =ROUND(J19*K19,0) | M19: =ROUND(L19*'Параметры плана'!$C$7,0) | N19: =IF(M19=0,0,F19/M19)
A20: Ноя 2026 | B20: =Инструменты!B8 | C20: =Инструменты!D8 | D20: =Инструменты!E8 | E20: =Инструменты!G8 | F20: =ROUND(Инструменты!I8*VLOOKUP(A20,'Параметры плана'!$A$21:$B$32,2,FALSE),0) | G20: =Инструменты!J8 | H20: =Инструменты!K8 | I20: =IF(G20=0,0,ROUND(J20/G20,0)) | J20: =IF(H20=0,0,ROUND(F20/H20,0)) | K20: =Инструменты!L8 | L20: =ROUND(J20*K20,0) | M20: =ROUND(L20*'Параметры плана'!$C$7,0) | N20: =IF(M20=0,0,F20/M20)
A21: Ноя 2026 | B21: =Инструменты!B9 | C21: =Инструменты!D9 | D21: =Инструменты!E9 | E21: =Инструменты!G9 | F21: =ROUND(Инструменты!I9*VLOOKUP(A21,'Параметры плана'!$A$21:$B$32,2,FALSE),0) | G21: =Инструменты!J9 | H21: =Инструменты!K9 | I21: =IF(G21=0,0,ROUND(J21/G21,0)) | J21: =IF(H21=0,0,ROUND(F21/H21,0)) | K21: =Инструменты!L9 | L21: =ROUND(J21*K21,0) | M21: =ROUND(L21*'Параметры плана'!$C$7,0) | N21: =IF(M21=0,0,F21/M21)
A22: Ноя 2026 | B22: =Инструменты!B10 | C22: =Инструменты!D10 | D22: =Инструменты!E10 | E22: =Инструменты!G10 | F22: =ROUND(Инструменты!I10*VLOOKUP(A22,'Параметры плана'!$A$21:$B$32,2,FALSE),0) | G22: =Инструменты!J10 | H22: =Инструменты!K10 | I22: =IF(G22=0,0,ROUND(J22/G22,0)) | J22: =IF(H22=0,0,ROUND(F22/H22,0)) | K22: =Инструменты!L10 | L22: =ROUND(J22*K22,0) | M22: =ROUND(L22*'Параметры плана'!$C$7,0) | N22: =IF(M22=0,0,F22/M22)
A23: Дек 2026 | B23: =Инструменты!B5 | C23: =Инструменты!D5 | D23: =Инструменты!E5 | E23: =Инструменты!G5 | F23: =ROUND(Инструменты!I5*VLOOKUP(A23,'Параметры плана'!$A$21:$B$32,2,FALSE),0) | G23: =Инструменты!J5 | H23: =Инструменты!K5 | I23: =IF(G23=0,0,ROUND(J23/G23,0)) | J23: =IF(H23=0,0,ROUND(F23/H23,0)) | K23: =Инструменты!L5 | L23: =ROUND(J23*K23,0) | M23: =ROUND(L23*'Параметры плана'!$C$7,0) | N23: =IF(M23=0,0,F23/M23)
A24: Дек 2026 | B24: =Инструменты!B6 | C24: =Инструменты!D6 | D24: =Инструменты!E6 | E24: =Инструменты!G6 | F24: =ROUND(Инструменты!I6*VLOOKUP(A24,'Параметры плана'!$A$21:$B$32,2,FALSE),0) | G24: =Инструменты!J6 | H24: =Инструменты!K6 | I24: =IF(G24=0,0,ROUND(J24/G24,0)) | J24: =IF(H24=0,0,ROUND(F24/H24,0)) | K24: =Инструменты!L6 | L24: =ROUND(J24*K24,0) | M24: =ROUND(L24*'Параметры плана'!$C$7,0) | N24: =IF(M24=0,0,F24/M24)
A25: Дек 2026 | B25: =Инструменты!B7 | C25: =Инструменты!D7 | D25: =Инструменты!E7 | E25: =Инструменты!G7 | F25: =ROUND(Инструменты!I7*VLOOKUP(A25,'Параметры плана'!$A$21:$B$32,2,FALSE),0) | G25: =Инструменты!J7 | H25: =Инструменты!K7 | I25: =IF(G25=0,0,ROUND(J25/G25,0)) | J25: =IF(H25=0,0,ROUND(F25/H25,0)) | K25: =Инструменты!L7 | L25: =ROUND(J25*K25,0) | M25: =ROUND(L25*'Параметры плана'!$C$7,0) | N25: =IF(M25=0,0,F25/M25)
A26: Дек 2026 | B26: =Инструменты!B8 | C26: =Инструменты!D8 | D26: =Инструменты!E8 | E26: =Инструменты!G8 | F26: =ROUND(Инструменты!I8*VLOOKUP(A26,'Параметры плана'!$A$21:$B$32,2,FALSE),0) | G26: =Инструменты!J8 | H26: =Инструменты!K8 | I26: =IF(G26=0,0,ROUND(J26/G26,0)) | J26: =IF(H26=0,0,ROUND(F26/H26,0)) | K26: =Инструменты!L8 | L26: =ROUND(J26*K26,0) | M26: =ROUND(L26*'Параметры плана'!$C$7,0) | N26: =IF(M26=0,0,F26/M26)
A27: Дек 2026 | B27: =Инструменты!B9 | C27: =Инструменты!D9 | D27: =Инструменты!E9 | E27: =Инструменты!G9 | F27: =ROUND(Инструменты!I9*VLOOKUP(A27,'Параметры плана'!$A$21:$B$32,2,FALSE),0) | G27: =Инструменты!J9 | H27: =Инструменты!K9 | I27: =IF(G27=0,0,ROUND(J27/G27,0)) | J27: =IF(H27=0,0,ROUND(F27/H27,0)) | K27: =Инструменты!L9 | L27: =ROUND(J27*K27,0) | M27: =ROUND(L27*'Параметры плана'!$C$7,0) | N27: =IF(M27=0,0,F27/M27)
A28: Дек 2026 | B28: =Инструменты!B10 | C28: =Инструменты!D10 | D28: =Инструменты!E10 | E28: =Инструменты!G10 | F28: =ROUND(Инструменты!I10*VLOOKUP(A28,'Параметры плана'!$A$21:$B$32,2,FALSE),0) | G28: =Инструменты!J10 | H28: =Инструменты!K10 | I28: =IF(G28=0,0,ROUND(J28/G28,0)) | J28: =IF(H28=0,0,ROUND(F28/H28,0)) | K28: =Инструменты!L10 | L28: =ROUND(J28*K28,0) | M28: =ROUND(L28*'Параметры плана'!$C$7,0) | N28: =IF(M28=0,0,F28/M28)
A29: Янв 2027 | B29: =Инструменты!B5 | C29: =Инструменты!D5 | D29: =Инструменты!E5 | E29: =Инструменты!G5 | F29: =ROUND(Инструменты!I5*VLOOKUP(A29,'Параметры плана'!$A$21:$B$32,2,FALSE),0) | G29: =Инструменты!J5 | H29: =Инструменты!K5 | I29: =IF(G29=0,0,ROUND(J29/G29,0)) | J29: =IF(H29=0,0,ROUND(F29/H29,0)) | K29: =Инструменты!L5 | L29: =ROUND(J29*K29,0) | M29: =ROUND(L29*'Параметры плана'!$C$7,0) | N29: =IF(M29=0,0,F29/M29)
A30: Янв 2027 | B30: =Инструменты!B6 | C30: =Инструменты!D6 | D30: =Инструменты!E6 | E30: =Инструменты!G6 | F30: =ROUND(Инструменты!I6*VLOOKUP(A30,'Параметры плана'!$A$21:$B$32,2,FALSE),0) | G30: =Инструменты!J6 | H30: =Инструменты!K6 | I30: =IF(G30=0,0,ROUND(J30/G30,0)) | J30: =IF(H30=0,0,ROUND(F30/H30,0)) | K30: =Инструменты!L6 | L30: =ROUND(J30*K30,0) | M30: =ROUND(L30*'Параметры плана'!$C$7,0) | N30: =IF(M30=0,0,F30/M30)
A31: Янв 2027 | B31: =Инструменты!B7 | C31: =Инструменты!D7 | D31: =Инструменты!E7 | E31: =Инструменты!G7 | F31: =ROUND(Инструменты!I7*VLOOKUP(A31,'Параметры плана'!$A$21:$B$32,2,FALSE),0) | G31: =Инструменты!J7 | H31: =Инструменты!K7 | I31: =IF(G31=0,0,ROUND(J31/G31,0)) | J31: =IF(H31=0,0,ROUND(F31/H31,0)) | K31: =Инструменты!L7 | L31: =ROUND(J31*K31,0) | M31: =ROUND(L31*'Параметры плана'!$C$7,0) | N31: =IF(M31=0,0,F31/M31)
A32: Янв 2027 | B32: =Инструменты!B8 | C32: =Инструменты!D8 | D32: =Инструменты!E8 | E32: =Инструменты!G8 | F32: =ROUND(Инструменты!I8*VLOOKUP(A32,'Параметры плана'!$A$21:$B$32,2,FALSE),0) | G32: =Инструменты!J8 | H32: =Инструменты!K8 | I32: =IF(G32=0,0,ROUND(J32/G32,0)) | J32: =IF(H32=0,0,ROUND(F32/H32,0)) | K32: =Инструменты!L8 | L32: =ROUND(J32*K32,0) | M32: =ROUND(L32*'Параметры плана'!$C$7,0) | N32: =IF(M32=0,0,F32/M32)
A33: Янв 2027 | B33: =Инструменты!B9 | C33: =Инструменты!D9 | D33: =Инструменты!E9 | E33: =Инструменты!G9 | F33: =ROUND(Инструменты!I9*VLOOKUP(A33,'Параметры плана'!$A$21:$B$32,2,FALSE),0) | G33: =Инструменты!J9 | H33: =Инструменты!K9 | I33: =IF(G33=0,0,ROUND(J33/G33,0)) | J33: =IF(H33=0,0,ROUND(F33/H33,0)) | K33: =Инструменты!L9 | L33: =ROUND(J33*K33,0) | M33: =ROUND(L33*'Параметры плана'!$C$7,0) | N33: =IF(M33=0,0,F33/M33)
A34: Янв 2027 | B34: =Инструменты!B10 | C34: =Инструменты!D10 | D34: =Инструменты!E10 | E34: =Инструменты!G10 | F34: =ROUND(Инструменты!I10*VLOOKUP(A34,'Параметры плана'!$A$21:$B$32,2,FALSE),0) | G34: =Инструменты!J10 | H34: =Инструменты!K10 | I34: =IF(G34=0,0,ROUND(J34/G34,0)) | J34: =IF(H34=0,0,ROUND(F34/H34,0)) | K34: =Инструменты!L10 | L34: =ROUND(J34*K34,0) | M34: =ROUND(L34*'Параметры плана'!$C$7,0) | N34: =IF(M34=0,0,F34/M34)
A35: Фев 2027 | B35: =Инструменты!B5 | C35: =Инструменты!D5 | D35: =Инструменты!E5 | E35: =Инструменты!G5 | F35: =ROUND(Инструменты!I5*VLOOKUP(A35,'Параметры плана'!$A$21:$B$32,2,FALSE),0) | G35: =Инструменты!J5 | H35: =Инструменты!K5 | I35: =IF(G35=0,0,ROUND(J35/G35,0)) | J35: =IF(H35=0,0,ROUND(F35/H35,0)) | K35: =Инструменты!L5 | L35: =ROUND(J35*K35,0) | M35: =ROUND(L35*'Параметры плана'!$C$7,0) | N35: =IF(M35=0,0,F35/M35)
A36: Фев 2027 | B36: =Инструменты!B6 | C36: =Инструменты!D6 | D36: =Инструменты!E6 | E36: =Инструменты!G6 | F36: =ROUND(Инструменты!I6*VLOOKUP(A36,'Параметры плана'!$A$21:$B$32,2,FALSE),0) | G36: =Инструменты!J6 | H36: =Инструменты!K6 | I36: =IF(G36=0,0,ROUND(J36/G36,0)) | J36: =IF(H36=0,0,ROUND(F36/H36,0)) | K36: =Инструменты!L6 | L36: =ROUND(J36*K36,0) | M36: =ROUND(L36*'Параметры плана'!$C$7,0) | N36: =IF(M36=0,0,F36/M36)
A37: Фев 2027 | B37: =Инструменты!B7 | C37: =Инструменты!D7 | D37: =Инструменты!E7 | E37: =Инструменты!G7 | F37: =ROUND(Инструменты!I7*VLOOKUP(A37,'Параметры плана'!$A$21:$B$32,2,FALSE),0) | G37: =Инструменты!J7 | H37: =Инструменты!K7 | I37: =IF(G37=0,0,ROUND(J37/G37,0)) | J37: =IF(H37=0,0,ROUND(F37/H37,0)) | K37: =Инструменты!L7 | L37: =ROUND(J37*K37,0) | M37: =ROUND(L37*'Параметры плана'!$C$7,0) | N37: =IF(M37=0,0,F37/M37)
A38: Фев 2027 | B38: =Инструменты!B8 | C38: =Инструменты!D8 | D38: =Инструменты!E8 | E38: =Инструменты!G8 | F38: =ROUND(Инструменты!I8*VLOOKUP(A38,'Параметры плана'!$A$21:$B$32,2,FALSE),0) | G38: =Инструменты!J8 | H38: =Инструменты!K8 | I38: =IF(G38=0,0,ROUND(J38/G38,0)) | J38: =IF(H38=0,0,ROUND(F38/H38,0)) | K38: =Инструменты!L8 | L38: =ROUND(J38*K38,0) | M38: =ROUND(L38*'Параметры плана'!$C$7,0) | N38: =IF(M38=0,0,F38/M38)
A39: Фев 2027 | B39: =Инструменты!B9 | C39: =Инструменты!D9 | D39: =Инструменты!E9 | E39: =Инструменты!G9 | F39: =ROUND(Инструменты!I9*VLOOKUP(A39,'Параметры плана'!$A$21:$B$32,2,FALSE),0) | G39: =Инструменты!J9 | H39: =Инструменты!K9 | I39: =IF(G39=0,0,ROUND(J39/G39,0)) | J39: =IF(H39=0,0,ROUND(F39/H39,0)) | K39: =Инструменты!L9 | L39: =ROUND(J39*K39,0) | M39: =ROUND(L39*'Параметры плана'!$C$7,0) | N39: =IF(M39=0,0,F39/M39)
A40: Фев 2027 | B40: =Инструменты!B10 | C40: =Инструменты!D10 | D40: =Инструменты!E10 | E40: =Инструменты!G10 | F40: =ROUND(Инструменты!I10*VLOOKUP(A40,'Параметры плана'!$A$21:$B$32,2,FALSE),0) | G40: =Инструменты!J10 | H40: =Инструменты!K10 | I40: =IF(G40=0,0,ROUND(J40/G40,0)) | J40: =IF(H40=0,0,ROUND(F40/H40,0)) | K40: =Инструменты!L10 | L40: =ROUND(J40*K40,0) | M40: =ROUND(L40*'Параметры плана'!$C$7,0) | N40: =IF(M40=0,0,F40/M40)
A41: Мар 2027 | B41: =Инструменты!B5 | C41: =Инструменты!D5 | D41: =Инструменты!E5 | E41: =Инструменты!G5 | F41: =ROUND(Инструменты!I5*VLOOKUP(A41,'Параметры плана'!$A$21:$B$32,2,FALSE),0) | G41: =Инструменты!J5 | H41: =Инструменты!K5 | I41: =IF(G41=0,0,ROUND(J41/G41,0)) | J41: =IF(H41=0,0,ROUND(F41/H41,0)) | K41: =Инструменты!L5 | L41: =ROUND(J41*K41,0) | M41: =ROUND(L41*'Параметры плана'!$C$7,0) | N41: =IF(M41=0,0,F41/M41)
...

Sheet Сводка по месяцам
A1: Сводка по месяцам: SUMIF с листа «Медиаплан на год»
A2: SUMIF с листа «Медиаплан на год»: месяцы различаются по сезонным весам с «Параметры плана». ДРР месяца = сумма расхода / сумма выручки, не среднее ДРР кампаний.
A4: Месяц | B4: Расход, ₽ | C4: Показы | D4: Клики | E4: Покупки | F4: Выручка, ₽ | G4: ДРР | H4: CPA, ₽
A5: Сен 2026 | B5: =SUMIF('Медиаплан на год'!A:A,A5,'Медиаплан на год'!F:F) | C5: =SUMIF('Медиаплан на год'!A:A,A5,'Медиаплан на год'!I:I) | D5: =SUMIF('Медиаплан на год'!A:A,A5,'Медиаплан на год'!J:J) | E5: =SUMIF('Медиаплан на год'!A:A,A5,'Медиаплан на год'!L:L) | F5: =SUMIF('Медиаплан на год'!A:A,A5,'Медиаплан на год'!M:M) | G5: =IF(F5=0,0,B5/F5) | H5: =IF(E5=0,0,B5/E5)
A6: Окт 2026 | B6: =SUMIF('Медиаплан на год'!A:A,A6,'Медиаплан на год'!F:F) | C6: =SUMIF('Медиаплан на год'!A:A,A6,'Медиаплан на год'!I:I) | D6: =SUMIF('Медиаплан на год'!A:A,A6,'Медиаплан на год'!J:J) | E6: =SUMIF('Медиаплан на год'!A:A,A6,'Медиаплан на год'!L:L) | F6: =SUMIF('Медиаплан на год'!A:A,A6,'Медиаплан на год'!M:M) | G6: =IF(F6=0,0,B6/F6) | H6: =IF(E6=0,0,B6/E6)
A7: Ноя 2026 | B7: =SUMIF('Медиаплан на год'!A:A,A7,'Медиаплан на год'!F:F) | C7: =SUMIF('Медиаплан на год'!A:A,A7,'Медиаплан на год'!I:I) | D7: =SUMIF('Медиаплан на год'!A:A,A7,'Медиаплан на год'!J:J) | E7: =SUMIF('Медиаплан на год'!A:A,A7,'Медиаплан на год'!L:L) | F7: =SUMIF('Медиаплан на год'!A:A,A7,'Медиаплан на год'!M:M) | G7: =IF(F7=0,0,B7/F7) | H7: =IF(E7=0,0,B7/E7)
A8: Дек 2026 | B8: =SUMIF('Медиаплан на год'!A:A,A8,'Медиаплан на год'!F:F) | C8: =SUMIF('Медиаплан на год'!A:A,A8,'Медиаплан на год'!I:I) | D8: =SUMIF('Медиаплан на год'!A:A,A8,'Медиаплан на год'!J:J) | E8: =SUMIF('Медиаплан на год'!A:A,A8,'Медиаплан на год'!L:L) | F8: =SUMIF('Медиаплан на год'!A:A,A8,'Медиаплан на год'!M:M) | G8: =IF(F8=0,0,B8/F8) | H8: =IF(E8=0,0,B8/E8)
A9: Янв 2027 | B9: =SUMIF('Медиаплан на год'!A:A,A9,'Медиаплан на год'!F:F) | C9: =SUMIF('Медиаплан на год'!A:A,A9,'Медиаплан на год'!I:I) | D9: =SUMIF('Медиаплан на год'!A:A,A9,'Медиаплан на год'!J:J) | E9: =SUMIF('Медиаплан на год'!A:A,A9,'Медиаплан на год'!L:L) | F9: =SUMIF('Медиаплан на год'!A:A,A9,'Медиаплан на год'!M:M) | G9: =IF(F9=0,0,B9/F9) | H9: =IF(E9=0,0,B9/E9)
A10: Фев 2027 | B10: =SUMIF('Медиаплан на год'!A:A,A10,'Медиаплан на год'!F:F) | C10: =SUMIF('Медиаплан на год'!A:A,A10,'Медиаплан на год'!I:I) | D10: =SUMIF('Медиаплан на год'!A:A,A10,'Медиаплан на год'!J:J) | E10: =SUMIF('Медиаплан на год'!A:A,A10,'Медиаплан на год'!L:L) | F10: =SUMIF('Медиаплан на год'!A:A,A10,'Медиаплан на год'!M:M) | G10: =IF(F10=0,0,B10/F10) | H10: =IF(E10=0,0,B10/E10)
A11: Мар 2027 | B11: =SUMIF('Медиаплан на год'!A:A,A11,'Медиаплан на год'!F:F) | C11: =SUMIF('Медиаплан на год'!A:A,A11,'Медиаплан на год'!I:I) | D11: =SUMIF('Медиаплан на год'!A:A,A11,'Медиаплан на год'!J:J) | E11: =SUMIF('Медиаплан на год'!A:A,A11,'Медиаплан на год'!L:L) | F11: =SUMIF('Медиаплан на год'!A:A,A11,'Медиаплан на год'!M:M) | G11: =IF(F11=0,0,B11/F11) | H11: =IF(E11=0,0,B11/E11)
A12: Апр 2027 | B12: =SUMIF('Медиаплан на год'!A:A,A12,'Медиаплан на год'!F:F) | C12: =SUMIF('Медиаплан на год'!A:A,A12,'Медиаплан на год'!I:I) | D12: =SUMIF('Медиаплан на год'!A:A,A12,'Медиаплан на год'!J:J) | E12: =SUMIF('Медиаплан на год'!A:A,A12,'Медиаплан на год'!L:L) | F12: =SUMIF('Медиаплан на год'!A:A,A12,'Медиаплан на год'!M:M) | G12: =IF(F12=0,0,B12/F12) | H12: =IF(E12=0,0,B12/E12)
A13: Май 2027 | B13: =SUMIF('Медиаплан на год'!A:A,A13,'Медиаплан на год'!F:F) | C13: =SUMIF('Медиаплан на год'!A:A,A13,'Медиаплан на год'!I:I) | D13: =SUMIF('Медиаплан на год'!A:A,A13,'Медиаплан на год'!J:J) | E13: =SUMIF('Медиаплан на год'!A:A,A13,'Медиаплан на год'!L:L) | F13: =SUMIF('Медиаплан на год'!A:A,A13,'Медиаплан на год'!M:M) | G13: =IF(F13=0,0,B13/F13) | H13: =IF(E13=0,0,B13/E13)
A14: Июн 2027 | B14: =SUMIF('Медиаплан на год'!A:A,A14,'Медиаплан на год'!F:F) | C14: =SUMIF('Медиаплан на год'!A:A,A14,'Медиаплан на год'!I:I) | D14: =SUMIF('Медиаплан на год'!A:A,A14,'Медиаплан на год'!J:J) | E14: =SUMIF('Медиаплан на год'!A:A,A14,'Медиаплан на год'!L:L) | F14: =SUMIF('Медиаплан на год'!A:A,A14,'Медиаплан на год'!M:M) | G14: =IF(F14=0,0,B14/F14) | H14: =IF(E14=0,0,B14/E14)
A15: Июл 2027 | B15: =SUMIF('Медиаплан на год'!A:A,A15,'Медиаплан на год'!F:F) | C15: =SUMIF('Медиаплан на год'!A:A,A15,'Медиаплан на год'!I:I) | D15: =SUMIF('Медиаплан на год'!A:A,A15,'Медиаплан на год'!J:J) | E15: =SUMIF('Медиаплан на год'!A:A,A15,'Медиаплан на год'!L:L) | F15: =SUMIF('Медиаплан на год'!A:A,A15,'Медиаплан на год'!M:M) | G15: =IF(F15=0,0,B15/F15) | H15: =IF(E15=0,0,B15/E15)
A16: Авг 2027 | B16: =SUMIF('Медиаплан на год'!A:A,A16,'Медиаплан на год'!F:F) | C16: =SUMIF('Медиаплан на год'!A:A,A16,'Медиаплан на год'!I:I) | D16: =SUMIF('Медиаплан на год'!A:A,A16,'Медиаплан на год'!J:J) | E16: =SUMIF('Медиаплан на год'!A:A,A16,'Медиаплан на год'!L:L) | F16: =SUMIF('Медиаплан на год'!A:A,A16,'Медиаплан на год'!M:M) | G16: =IF(F16=0,0,B16/F16) | H16: =IF(E16=0,0,B16/E16)
A17: Итого год | B17: =SUM(B5:B16) | C17: =SUM(C5:C16) | D17: =SUM(D5:D16) | E17: =SUM(E5:E16) | F17: =SUM(F5:F16) | G17: =IF(F17=0,0,B17/F17) | H17: =IF(E17=0,0,B17/E17)
A19: Комментарий к расчёту
A20: Месяцы различаются: SUMIF тянет расход с сетки года, где к базовому бюджету кампании умножен сезонный вес с «Параметров плана». ДРР месяца считаю от сумм, не усредняю ДРР кампаний: иначе категория с ДРР ~30% «спрячется» за брендом. Сентябрь/октябрь и январь выше июня/июля — это школьный и зимний спрос; сумма 12 месяцев = 12 млн ₽, веса и логика сдвига описаны на «Параметрах плана».

Sheet Сводка за год
A1: Сводка за год: инструменты и KPI (SUMIF с «Медиаплан на год»)
A2: Коридор ДРР 15–25% — условие приёмки плана. Годовые KPI — сумма 12 сезонных месяцев с сетки года; доли и бенчи не меняются.
A4: Кампания | B4: Тип площадки | C4: Доп. инструменты | D4: Доля | E4: Расход год, ₽ | F4: Клики год | G4: Покупки год | H4: Выручка год, ₽ | I4: ДРР | J4: CPA, ₽ | K4: Вклад в покупки
A5: =Инструменты!B5 | B5: =Инструменты!D5 | C5: =Инструменты!E5 | D5: =Инструменты!H5 | E5: =SUMIF('Медиаплан на год'!B:B,A5,'Медиаплан на год'!F:F) | F5: =SUMIF('Медиаплан на год'!B:B,A5,'Медиаплан на год'!J:J) | G5: =SUMIF('Медиаплан на год'!B:B,A5,'Медиаплан на год'!L:L) | H5: =SUMIF('Медиаплан на год'!B:B,A5,'Медиаплан на год'!M:M) | I5: =IF(H5=0,0,E5/H5) | J5: =IF(G5=0,0,E5/G5) | K5: =IF(G$11=0,0,G5/G$11)
A6: =Инструменты!B6 | B6: =Инструменты!D6 | C6: =Инструменты!E6 | D6: =Инструменты!H6 | E6: =SUMIF('Медиаплан на год'!B:B,A6,'Медиаплан на год'!F:F) | F6: =SUMIF('Медиаплан на год'!B:B,A6,'Медиаплан на год'!J:J) | G6: =SUMIF('Медиаплан на год'!B:B,A6,'Медиаплан на год'!L:L) | H6: =SUMIF('Медиаплан на год'!B:B,A6,'Медиаплан на год'!M:M) | I6: =IF(H6=0,0,E6/H6) | J6: =IF(G6=0,0,E6/G6) | K6: =IF(G$11=0,0,G6/G$11)
A7: =Инструменты!B7 | B7: =Инструменты!D7 | C7: =Инструменты!E7 | D7: =Инструменты!H7 | E7: =SUMIF('Медиаплан на год'!B:B,A7,'Медиаплан на год'!F:F) | F7: =SUMIF('Медиаплан на год'!B:B,A7,'Медиаплан на год'!J:J) | G7: =SUMIF('Медиаплан на год'!B:B,A7,'Медиаплан на год'!L:L) | H7: =SUMIF('Медиаплан на год'!B:B,A7,'Медиаплан на год'!M:M) | I7: =IF(H7=0,0,E7/H7) | J7: =IF(G7=0,0,E7/G7) | K7: =IF(G$11=0,0,G7/G$11)
A8: =Инструменты!B8 | B8: =Инструменты!D8 | C8: =Инструменты!E8 | D8: =Инструменты!H8 | E8: =SUMIF('Медиаплан на год'!B:B,A8,'Медиаплан на год'!F:F) | F8: =SUMIF('Медиаплан на год'!B:B,A8,'Медиаплан на год'!J:J) | G8: =SUMIF('Медиаплан на год'!B:B,A8,'Медиаплан на год'!L:L) | H8: =SUMIF('Медиаплан на год'!B:B,A8,'Медиаплан на год'!M:M) | I8: =IF(H8=0,0,E8/H8) | J8: =IF(G8=0,0,E8/G8) | K8: =IF(G$11=0,0,G8/G$11)
A9: =Инструменты!B9 | B9: =Инструменты!D9 | C9: =Инструменты!E9 | D9: =Инструменты!H9 | E9: =SUMIF('Медиаплан на год'!B:B,A9,'Медиаплан на год'!F:F) | F9: =SUMIF('Медиаплан на год'!B:B,A9,'Медиаплан на год'!J:J) | G9: =SUMIF('Медиаплан на год'!B:B,A9,'Медиаплан на год'!L:L) | H9: =SUMIF('Медиаплан на год'!B:B,A9,'Медиаплан на год'!M:M) | I9: =IF(H9=0,0,E9/H9) | J9: =IF(G9=0,0,E9/G9) | K9: =IF(G$11=0,0,G9/G$11)
A10: =Инструменты!B10 | B10: =Инструменты!D10 | C10: =Инструменты!E10 | D10: =Инструменты!H10 | E10: =SUMIF('Медиаплан на год'!B:B,A10,'Медиаплан на год'!F:F) | F10: =SUMIF('Медиаплан на год'!B:B,A10,'Медиаплан на год'!J:J) | G10: =SUMIF('Медиаплан на год'!B:B,A10,'Медиаплан на год'!L:L) | H10: =SUMIF('Медиаплан на год'!B:B,A10,'Медиаплан на год'!M:M) | I10: =IF(H10=0,0,E10/H10) | J10: =IF(G10=0,0,E10/G10) | K10: =IF(G$11=0,0,G10/G$11)
A11: Итого год | D11: =SUM(D5:D10) | E11: =SUM(E5:E10) | F11: =SUM(F5:F10) | G11: =SUM(G5:G10) | H11: =SUM(H5:H10) | I11: =IF(H11=0,0,E11/H11) | J11: =IF(G11=0,0,E11/G11) | K11: =SUM(K5:K10)
A13: Сверка с сеткой года
A14: Расход (сводка) | B14: =E11 | C14: Расход (сетка) | D14: ='Медиаплан на год'!F77 | E14: Расхождение | F14: =B14-D14
A15: Выручка (сводка) | B15: =H11 | C15: Выручка (сетка) | D15: ='Медиаплан на год'!M77 | E15: Расхождение | F15: =B15-D15
A16: ДРР в коридоре 15–25% | B16: =IF(AND(I11>=0.15,I11<=0.25),"Да","Нет — проверьте бенчи")
A18: Комментарий к расчёту
A19: Приёмка плана — годовой ДРР в коридоре 15–25% (строка проверки). Годовые KPI — сумма 12 сезонных месяцев с «Медиаплана на год», не flat × 12. По вкладу в покупки лидирует не «самая дешёвая» кампания, а связка: категорийный Поиск даёт объём, ретаргет РСЯ — догрев, бренд — дешёвый захват своего спроса. Автотаргетинг с худшим CR не ломает год, потому что доля 10% и изолирована. После старта сверяем факт CR по каждому месту показа; бенчи в плане — рабочая гипотеза, не статистика кабинета ECCO.
